Workbook

Sheet README
B2: ORACLE FUSION CLOUD — IMPLEMENTATION ESTIMATOR
B3: README — How to Use This Estimator
B5: 1. PURPOSE & SCOPE
B6: This workbook is a benchmark-calibrated effort estimation tool for Oracle Fusion Cloud implementations. It covers the full suite — HCM, ERP Financials, Procurement, SCM, CX, EPM, Integration, Data Migration, Reporting, Security, Testing, OCM, and Programme Management — across all SDLC phases from Inception through Post Go-Live Support. It is designed for use by Delivery Leads, Solution Architects, and Estimation CoE practitioners to produce a defensible, assumption-documented effort estimate at proposal, planning, or re-baselining stages. All unit effort values are grounded in published industry benchmarks (Everest Group, Forrester TEI, Gartner, SFIA v8) and are clearly sourced in the Benchmark Library tab.
B8: 2. WORKBOOK STRUCTURE — TAB GUIDE
B9: Tab Name | C9: Purpose | D9: Input / Output
B10: README | C10: This guide. Start here. | D10: Reference
B11: Cover | C11: Project metadata — client name, modules, deployment model, version. | D11: Input
B12: Assumptions | C12: Master control panel. All global levers: project parameters, rate card, complexity multipliers, SDLC phase splits. Change inputs here first. | D12: Input
B13: Module Estimator | C13: Core estimation matrix. 68 components across 12 Oracle Fusion pillars. Each row has: component, complexity, volume driver, unit effort, benchmark source, phase split %, complexity multiplier, base effort, and adjusted effort. | D13: Input + Calc
B14: Benchmark Library | C14: Read-only reference. Unit rates and productivity benchmarks from Everest Group (2023), Forrester TEI (2022–24), Gartner (2022), and SFIA v8. Low / Typical / High ranges per component type. | D14: Reference
B15: Effort Summary | C15: Auto-rolled-up effort by module and by SDLC phase. Pulls from Module Estimator and Assumptions. Includes contingency. | D15: Output
B16: FTE & Role Plan | C16: Role definitions, responsibilities, blended rates, and an 18-month FTE loading grid (month-by-month headcount per role). | D16: Output
B17: Assumptions & Risks | C17: 18 standard estimation assumptions, 11 exclusions, and a 14-row risk register with probability, impact, effort adder %, and mitigations. | D17: Reference + Output
B18: Cost Model | C18: Effort × blended rates → total engagement cost by role band. Includes contingency, management reserve, and phased cost split by SDLC phase. | D18: Output
B20: 3. HOW TO USE THIS ESTIMATOR — STEP BY STEP
B21: Step 1 | C21: Fill in the Cover tab
C22: Enter the client name, Oracle modules in scope, deployment model, industry, and date. This is metadata only — it does not affect calculations.
B23: Step 2 | C23: Set global parameters in Assumptions → Section A
C24: Enter: project duration, number of modules, legal entities/countries, integration count (simple vs complex), data migration object count, report count, CEMLI extensions count, contingency %, working days per month, and onshore/offshore split. These drive the cost model and effort summary.
B25: Step 3 | C25: Set your Rate Card in Assumptions → Section B
C26: Review and adjust onshore and offshore daily rates per role band. Blended rates are auto-calculated based on the onshore/offshore split you entered in Step 2.
B27: Step 4 | C27: Adjust complexity in Assumptions → Section C (optional)
C28: The four complexity multipliers (Low=0.7×, Medium=1.0×, High=1.4×, Very High=1.9×) are pre-set to industry norms. Adjust only if your organisation has calibrated data that differs from benchmarks.
B29: Step 5 | C29: Set Volume Drivers and Complexity in Module Estimator — the most important step
C30: For each component row in the Module Estimator tab: • COMPLEXITY (column D): set to L / M / H / VH based on your assessment of this specific component for this client. Drives the multiplier in column M. • VOLUME DRIVER (column E): enter the count of how many of this object you are building. See Section 4 below for a full explanation of what volume means per component type. This is the most sensitive input — small changes here create the largest swings in total effort.
B31: Step 6 | C31: Read outputs — do not edit green cells
C32: Base Effort (col N) = Volume × Unit Effort. Adjusted Effort (col O) = Base Effort × Complexity Multiplier. Totals with contingency are in the bottom two rows of the Module Estimator tab. The Effort Summary, FTE Plan, and Cost Model tabs auto-update from these.
B33: Step 7 | C33: Review and tailor Assumptions & Risks
C34: Check all 18 standard assumptions still hold for your engagement. Strike out any that do not apply. Add engagement-specific assumptions. Review the 14 risk rows — adjust probability/impact and add risks specific to this client's context.
B35: Step 8 | C35: Present the Cost Model
C36: The Cost Model tab shows total engagement cost by role band (base + contingency), plus an indicative cost split by SDLC phase. Use this as the basis for your commercial proposal or internal budget submission.
B38: 4. UNDERSTANDING THE VOLUME DRIVER COLUMN (Module Estimator, Column E)
B39: The Volume Driver column answers one question: how many of this thing are we building or configuring? It is separate from complexity. Complexity adjusts the effort rate; volume adjusts how many times you apply that rate. The formula is simply: Base Effort (Days) = Volume Driver × Unit Effort per item Components fall into two distinct categories, and misunderstanding this distinction is the most common source of estimation error.
B41: CATEGORY A — Configuration Components (Volume = 1 in almost all cases)
B42: These are modules or functional areas you configure once as a whole. The unit effort already prices the full end-to-end configuration effort for a standard deployment of that component. Volume = 1 means 'we are configuring this module once for this client.' Increasing volume above 1 is only appropriate when you are genuinely deploying the same component multiple times — for example, configuring Payroll separately for 3 countries with distinct legislative rules (Volume = 3) or setting up separate AR configurations for 4 legal entities with different billing rules (Volume = 4).
B43: Component | C43: Typical Volume | D43: Rationale
B44: General Ledger & Chart of Accounts | C44: 1 | D44: One CoA design per deployment, regardless of account count
B45: Absence Management | C45: 1 | D45: One Absence module configuration, even if many absence types
B46: Payroll Run & Reconciliation | C46: 1 | D46: One payroll process design; use 3 if 3 countries with separate payrolls
...

Sheet Cover
B2: ORACLE FUSION CLOUD — IMPLEMENTATION ESTIMATOR
B3: Enterprise-Grade Effort, FTE & Cost Estimation Framework | Benchmark-Calibrated
B5: Client / Engagement Name | C5: <<Enter Name>>
B6: Oracle Modules in Scope | C6: <<e.g. HCM, ERP, SCM>>
B7: Deployment Model | C7: <<Cloud / Hybrid>>
B8: Industry Vertical | C8: <<e.g. Manufacturing, BFSI>>
B9: Estimator Version | C9: v1.0
B10: Prepared By | C10: <<Name>>
B11: Date | C11: <<DD-MMM-YYYY>>
B12: Estimation Basis | C12: Benchmark-calibrated (Forrester TEI, Everest Group, Gartner)
B15: WORKBOOK NAVIGATION GUIDE
B16: 1. Assumptions | C16: Global levers – team size, contingency %, blended rates, SDLC coverage
B17: 2. Module Estimator | C17: Component-level effort matrix: all Fusion modules × complexity × phase
B18: 3. Benchmark Library | C18: Forrester / Everest / Gartner / SFIA unit rates & productivity benchmarks
B19: 4. Effort Summary | C19: Consolidated effort by module, phase, role — auto-rolled up from Module sheet
B20: 5. FTE & Role Plan | C20: FTE loading plan per role per month across project timeline
B21: 6. Assumptions & Risks | C21: Standard estimation assumptions, exclusions, and risk register
B22: 7. Cost Model | C22: Effort × blended rates → cost by role band and total engagement cost
B24: INPUT CELLS: Amber fill | FORMULA CELLS: Blue text | OUTPUT CELLS: Green fill

Sheet Assumptions
B1: GLOBAL ASSUMPTIONS & LEVERS — Oracle Fusion Implementation Estimator
B3: A. PROJECT PARAMETERS
B4: Parameter | C4: Value | D4: Unit | E4: Min | F4: Max | G4: Source / Note
B5: Project Duration (months) | C5: 18 | D5: months | E5: 12 | F5: 36 | G5: Everest Group Oracle Cloud avg 14-22 mths (mid-market to enterprise)
B6: No. of Oracle Modules in Scope | C6: 5 | D6: count | E6: 1 | F6: 12 | G6: Adjustable — see Module Estimator tab
B7: No. of Legal Entities / Countries | C7: 3 | D7: count | E7: 1 | F7: 50 | G7: Drives data migration & localisation complexity
B8: No. of Integrations (Interfaces) | C8: 25 | D8: count | E8: 5 | F8: 150 | G8: Gartner: avg 30-50 for mid-market ERP
B9: No. of Data Migration Objects | C9: 15 | D9: count | E9: 5 | F9: 120 | G9: Everest: typical 10-40 objects per deployment
B10: No. of Custom Reports / Analytics | C10: 40 | D10: count | E10: 10 | F10: 300 | G10: Forrester TEI: 30-60 standard; 60-150 complex
B11: No. of Custom Extensions (CEMLI) | C11: 10 | D11: count | E11: 0 | F11: 100 | G11: Best practice: minimise to <15% of OOB
B12: No. of Integrations – Complex | C12: 8 | D12: count | E12: 0 | F12: 50 | G12: Bidirectional, real-time, event-driven
B13: No. of Integrations – Simple | C13: 17 | D13: count | E13: 0 | F13: 100 | G13: Batch/file-based, one-way
B14: Contingency % | C14: 15 | D14: % | E14: 10 | F14: 25 | G14: PMI standard: 10-20%; Oracle programmes 15%
B15: Management Reserve % | C15: 5 | D15: % | E15: 3 | F15: 10 | G15: Programme-level buffer over contingency
B16: Working Hours per Day | C16: 8 | D16: hrs | E16: 7 | F16: 9 | G16: Standard billing day
... B19: Offshore % | C19: 70 | D19: % | E19: 0 | F19: 100 | G19: Should sum to 100% with Onshore %
B21: B. RATE CARD — BLENDED DAILY RATES (USD)
B22: Role / Band | C22: Onshore Rate ($/day) | D22: Offshore Rate ($/day) | E22: Blended Rate ($/day) | F22: Seniority Level | G22: Typical Engagement %
B23: Programme Director / Engagement Lead | C23: 2200 | D23: 900 | E23: =Assumptions!C17*C23/100 + Assumptions!C18*D23/100 -> 710 | F23: Partner / Director | G23: 3%
B24: Solution Architect | C24: 1800 | D24: 750 | E24: =Assumptions!C17*C24/100 + Assumptions!C18*D24/100 -> 585 | F24: Senior Manager | G24: 5%
B25: Functional Lead (per module) | C25: 1500 | D25: 600 | E25: =Assumptions!C17*C25/100 + Assumptions!C18*D25/100 -> 480 | F25: Senior Manager | G25: 12%
B26: Technical Lead (Integration/Dev) | C26: 1600 | D26: 650 | E26: =Assumptions!C17*C26/100 + Assumptions!C18*D26/100 -> 515 | F26: Senior Manager | G26: 8%
B27: Functional Consultant (Senior) | C27: 1200 | D27: 480 | E27: =Assumptions!C17*C27/100 + Assumptions!C18*D27/100 -> 384 | F27: Manager | G27: 20%
B28: Functional Consultant (Mid) | C28: 900 | D28: 360 | E28: =Assumptions!C17*C28/100 + Assumptions!C18*D28/100 -> 288 | F28: Senior Associate | G28: 18%
B29: Technical Developer | C29: 950 | D29: 380 | E29: =Assumptions!C17*C29/100 + Assumptions!C18*D29/100 -> 304 | F29: Senior Associate | G29: 10%
B30: Data Migration Specialist | C30: 1100 | D30: 440 | E30: =Assumptions!C17*C30/100 + Assumptions!C18*D30/100 -> 352 | F30: Manager | G30: 7%
B31: Change Management / OCM Lead | C31: 1300 | D31: 520 | E31: =Assumptions!C17*C31/100 + Assumptions!C18*D31/100 -> 416 | F31: Manager | G31: 5%
B32: Testing Lead / QA Manager | C32: 1000 | D32: 400 | E32: =Assumptions!C17*C32/100 + Assumptions!C18*D32/100 -> 320 | F32: Manager | G32: 5%
B33: Infrastructure / Cloud Engineer | C33: 1100 | D33: 450 | E33: =Assumptions!C17*C33/100 + Assumptions!C18*D33/100 -> 355 | F33: Senior Associate | G33: 4%
B34: Project Manager | C34: 1400 | D34: 560 | E34: =Assumptions!C17*C34/100 + Assumptions!C18*D34/100 -> 448 | F34: Manager | G34: 3%
B36: C. COMPLEXITY MULTIPLIERS
B37: Complexity Level | C37: Multiplier | D37: Selection Criteria | E37: Config Example | F37: Custom Example | G37: Data Migration Example
B38: Low | C38: 0.7 | D38: • OOB / standard Oracle functionality; minimal configuration beyond defaults • Single legal entity or business unit; no country-specific localisation • Processes closely match Oracle standard; no workarounds or process redesign • Standard approval workflow (1–2 levels); standard RBAC roles sufficient • Source data is clean, well-structured, available in compatible format • Integration is one-way batch/file-based (SFTP/FTP); no transformation logic | E38: › Single-country absence plans & holiday calendars › Standard expense policy with OOB approval › Item category setup with standard attributes | F38: › One-way batch SFTP integration (file-based) › Standard OTBI report using a single subject area › Simple page personalisation (hide/show fields) | G38: › Reference data (departments, grades, jobs) — clean single source › Supplier master from single ERP, no duplicates, standard fields › GL chart of accounts with clear legacy mapping
B39: Medium | C39: 1 | D39: • Some configuration beyond OOB; guided by Oracle best practice • 2–5 legal entities or business units sharing common structures • Minor process deviations handled via Oracle flexfields or lookups • Standard multi-level approval workflow (2–3 levels); standard security model • Source data requires moderate cleansing; mostly 1-to-1 field mapping • Standard REST/SOAP API integration; moderate transformation logic | E39: › Multi-entity GL with intercompany accounting (3 entities) › AP invoice approval with 3-level BPM workflow › Payroll element setup for a single-country payroll | F39: › OIC REST API integration (inbound/outbound, moderate mapping) › OTBI report across 2 subject areas with calculated measures › BPM workflow extension with conditional routing | G39: › Employee master from a single HR system with standard fields › Open AP invoices from a structured ERP with known schema › Item master with 50–70% direct attribute mapping
B40: High | C40: 1.4 | D40: • Significant complexity; multiple exceptions to OOB process • 6–15 legal entities, multi-country, or cross-pillar dependencies • Legislative or regulatory requirements driving non-standard configuration • Complex multi-level approval hierarchies; data security policy design • Source data is poor quality, fragmented across systems, or unstructured • Real-time or bidirectional integration; event-driven or orchestrated flows | E40: › Multi-country payroll with country-specific tax localisations (3+ countries) › WMS warehouse layout with advanced picking, putaway & replenishment rules › Security RBAC design with SoD conflict identification and remediation | F40: › Bidirectional real-time OIC integration with complex transformation logic › Custom payroll Fast Formula with tax override and conditional logic › OAC dashboard with cross-pillar KPIs and multi-source calculated metrics | G40: › Employee data from 3+ HR systems with conflicting schemas › Fixed assets with full depreciation history and NBV reconciliation › BOM/routing from legacy MRP with non-standard structure and UoM
B41: Very High | C41: 1.9 | D41: • Heavily customised or non-standard process; Oracle OOB not fit for purpose • 15+ legal entities, global rollout, or highly regulated (BFSI, Pharma, Defence) • High CEMLI dependency; multiple custom extensions interacting with each other • Real-time multi-system orchestration with complex event handling and retry logic • Legacy data with no clear mapping, large volumes, or critical statutory reconciliation • Concurrent go-live across multiple countries or business units in a single cutover | E41: › Global payroll across 10+ countries with unique legislation per country › Holding company consolidation with complex minority interest & FX elimination › Manufacturing with multi-level BOM, shop floor control, and IoT sensor integration | F41: › ODA chatbot with NLP + multi-system backend orchestration › Multi-system integration hub (ERP + HCM + CRM + 3PL + Banking) › Custom statutory report replacing a government submission format | G41: › Legacy COBOL mainframe data with reverse-engineered schema › Multi-country payroll balances with local statutory year-end carryforward › Inventory from 5+ legacy WMS systems with conflicting UoM, codes and structures
B43: D. SDLC PHASE EFFORT DISTRIBUTION (% of Total Effort)
B44: SDLC Phase | C44: % Effort | D44: Oracle AIM/OUM Ref | E44: Key Activities
B45: Inception / Mobilisation | C45: 0.05 | D45: Phase 0 | E45: Kick-off, infra setup, team onboarding, governance
B46: Discover & Assess (CRP1) | C46: 0.12 | D46: OUM: Inception | E46: Current state, gap analysis, Conference Room Pilot 1
...

Sheet Module Estimator
B1: MODULE-LEVEL EFFORT ESTIMATION MATRIX — Oracle Fusion Cloud Implementation
B2: Enter volumetric drivers (yellow cells). Complexity auto-applies benchmark unit effort from Benchmark Library.
B4: Module / Pillar | C4: Component / Sub-Process | D4: Complexity (L/M/H/VH) | E4: Volume Driver (Count) | F4: Unit Effort (Days) — OOB | G4: Benchmark Source | H4: Phase: Discover (%) | I4: Phase: Design (%) | J4: Phase: Build (%) | K4: Phase: Test (%) | L4: Phase: Deploy (%) | M4: Complexity Multiplier | N4: Base Effort (Days) | O4: Adjusted Effort (Days) | P4: Primary Role
B6: ▼ COMPLEXITY GUIDE — How to select L / M / H / VH for each row (Column D)
B7: Select the code that best describes the majority of the work in this row. When in doubt between two levels, always choose the higher one and document your rationale. Multipliers are applied automatically from the Assumptions tab.
B8: Level (Code) | E8: Selection Criteria | P8: Typical Example for this Sheet
B9: Low (L) ×HL:0.7× | E9: • OOB / standard Oracle functionality; minimal configuration beyond defaults • Single legal entity or business unit; no country-specific localisation • Processes closely match Oracle standard; no workarounds or process redesign • Standard approval workflow (1–2 levels); standard RBAC roles sufficient • Source data is clean, well-structured, available in compatible format • Integration is one-way batch/file-based (SFTP/FTP); no transformation logic | P9: › Single-country absence plans & holiday calendars › Standard expense policy with OOB approval › Item category setup with standard attributes
B10: Medium (M) ×HL:1.0× | E10: • Some configuration beyond OOB; guided by Oracle best practice • 2–5 legal entities or business units sharing common structures • Minor process deviations handled via Oracle flexfields or lookups • Standard multi-level approval workflow (2–3 levels); standard security model • Source data requires moderate cleansing; mostly 1-to-1 field mapping • Standard REST/SOAP API integration; moderate transformation logic | P10: › Multi-entity GL with intercompany accounting (3 entities) › AP invoice approval with 3-level BPM workflow › Payroll element setup for a single-country payroll
B11: High (H) ×HL:1.4× | E11: • Significant complexity; multiple exceptions to OOB process • 6–15 legal entities, multi-country, or cross-pillar dependencies • Legislative or regulatory requirements driving non-standard configuration • Complex multi-level approval hierarchies; data security policy design • Source data is poor quality, fragmented across systems, or unstructured • Real-time or bidirectional integration; event-driven or orchestrated flows | P11: › Multi-country payroll with country-specific tax localisations (3+ countries) › WMS warehouse layout with advanced picking, putaway & replenishment rules › Security RBAC design with SoD conflict identification and remediation
B12: Very High (VH) ×HL:1.9× | E12: • Heavily customised or non-standard process; Oracle OOB not fit for purpose • 15+ legal entities, global rollout, or highly regulated (BFSI, Pharma, Defence) • High CEMLI dependency; multiple custom extensions interacting with each other • Real-time multi-system orchestration with complex event handling and retry logic • Legacy data with no clear mapping, large volumes, or critical statutory reconciliation • Concurrent go-live across multiple countries or business units in a single cutover | P12: › Global payroll across 10+ countries with unique legislation per country › Holding company consolidation with complex minority interest & FX elimination › Manufacturing with multi-level BOM, shop floor control, and IoT sensor integration
B14: HCM – Core HR | C14: Enterprise Structures & Legal Entities | D14: M | E14: 3 | F14: 12 | G14: Everest 2023 | H14: 0.15 | I14: 0.2 | J14: 0.45 | K14: 0.15 | L14: 0.05 | M14: =IF(D14="L",Assumptions!C38,IF(D14="M",Assumptions!C39,IF(D14="H",Assumptions!C40,IF(D14="VH",Assumptions!C41,1)))) -> 1 | N14: =E14*F14 -> 36 | O14: =N14*M14 -> 36 | P14: Functional Consultant
B15: HCM – Core HR | C15: Workforce Structures (Dept/Grade/Position) | D15: M | E15: 1 | F15: 8 | G15: Everest 2023 | H15: 0.15 | I15: 0.2 | J15: 0.45 | K15: 0.15 | L15: 0.05 | M15: =IF(D15="L",Assumptions!C38,IF(D15="M",Assumptions!C39,IF(D15="H",Assumptions!C40,IF(D15="VH",Assumptions!C41,1)))) -> 1 | N15: =E15*F15 -> 8 | O15: =N15*M15 -> 8 | P15: Functional Consultant
B16: HCM – Core HR | C16: Employee Lifecycle Management | D16: M | E16: 1 | F16: 10 | G16: Gartner 2022 | H16: 0.1 | I16: 0.2 | J16: 0.5 | K16: 0.15 | L16: 0.05 | M16: =IF(D16="L",Assumptions!C38,IF(D16="M",Assumptions!C39,IF(D16="H",Assumptions!C40,IF(D16="VH",Assumptions!C41,1)))) -> 1 | N16: =E16*F16 -> 10 | O16: =N16*M16 -> 10 | P16: Functional Lead
B17: HCM – Core HR | C17: Absence Management | D17: M | E17: 1 | F17: 8 | G17: Forrester TEI | H17: 0.1 | I17: 0.2 | J17: 0.5 | K17: 0.15 | L17: 0.05 | M17: =IF(D17="L",Assumptions!C38,IF(D17="M",Assumptions!C39,IF(D17="H",Assumptions!C40,IF(D17="VH",Assumptions!C41,1)))) -> 1 | N17: =E17*F17 -> 8 | O17: =N17*M17 -> 8 | P17: Functional Consultant
B18: HCM – Core HR | C18: Document Management & Person Info | D18: L | E18: 1 | F18: 5 | G18: Everest 2023 | H18: 0.1 | I18: 0.15 | J18: 0.55 | K18: 0.15 | L18: 0.05 | M18: =IF(D18="L",Assumptions!C38,IF(D18="M",Assumptions!C39,IF(D18="H",Assumptions!C40,IF(D18="VH",Assumptions!C41,1)))) -> 0.7 | N18: =E18*F18 -> 5 | O18: =N18*M18 -> 3.5 | P18: Functional Consultant
B19: HCM – Payroll | C19: Payroll Element Setup & Fast Formulas | D19: H | E19: 1 | F19: 20 | G19: Everest 2023 | H19: 0.1 | I19: 0.2 | J19: 0.45 | K19: 0.2 | L19: 0.05 | M19: =IF(D19="L",Assumptions!C38,IF(D19="M",Assumptions!C39,IF(D19="H",Assumptions!C40,IF(D19="VH",Assumptions!C41,1)))) -> 1.4 | N19: =E19*F19 -> 20 | O19: =N19*M19 -> 28 | P19: Functional Lead
B20: HCM – Payroll | C20: Payroll Run & Reconciliation | D20: H | E20: 1 | F20: 18 | G20: Forrester TEI | H20: 0.1 | I20: 0.15 | J20: 0.45 | K20: 0.25 | L20: 0.05 | M20: =IF(D20="L",Assumptions!C38,IF(D20="M",Assumptions!C39,IF(D20="H",Assumptions!C40,IF(D20="VH",Assumptions!C41,1)))) -> 1.4 | N20: =E20*F20 -> 18 | O20: =N20*M20 -> 25.2 | P20: Functional Lead
B21: HCM – Payroll | C21: Tax Localisation & Costing | D21: H | E21: 3 | F21: 15 | G21: Gartner 2022 | H21: 0.1 | I21: 0.2 | J21: 0.4 | K21: 0.25 | L21: 0.05 | M21: =IF(D21="L",Assumptions!C38,IF(D21="M",Assumptions!C39,IF(D21="H",Assumptions!C40,IF(D21="VH",Assumptions!C41,1)))) -> 1.4 | N21: =E21*F21 -> 45 | O21: =N21*M21 -> 63 | P21: Technical Developer
B22: HCM – Talent | C22: Recruitment & Candidate Management | D22: M | E22: 1 | F22: 10 | G22: Forrester TEI | H22: 0.1 | I22: 0.2 | J22: 0.5 | K22: 0.15 | L22: 0.05 | M22: =IF(D22="L",Assumptions!C38,IF(D22="M",Assumptions!C39,IF(D22="H",Assumptions!C40,IF(D22="VH",Assumptions!C41,1)))) -> 1 | N22: =E22*F22 -> 10 | O22: =N22*M22 -> 10 | P22: Functional Consultant
B23: HCM – Talent | C23: Performance Management & Goal Setting | D23: M | E23: 1 | F23: 8 | G23: Everest 2023 | H23: 0.1 | I23: 0.2 | J23: 0.5 | K23: 0.15 | L23: 0.05 | M23: =IF(D23="L",Assumptions!C38,IF(D23="M",Assumptions!C39,IF(D23="H",Assumptions!C40,IF(D23="VH",Assumptions!C41,1)))) -> 1 | N23: =E23*F23 -> 8 | O23: =N23*M23 -> 8 | P23: Functional Consultant
B24: HCM – Talent | C24: Learning Management (OLM) | D24: M | E24: 1 | F24: 10 | G24: Forrester TEI | H24: 0.1 | I24: 0.2 | J24: 0.5 | K24: 0.15 | L24: 0.05 | M24: =IF(D24="L",Assumptions!C38,IF(D24="M",Assumptions!C39,IF(D24="H",Assumptions!C40,IF(D24="VH",Assumptions!C41,1)))) -> 1 | N24: =E24*F24 -> 10 | O24: =N24*M24 -> 10 | P24: Functional Consultant
B25: HCM – Benefits | C25: Benefit Plans & Eligibility | D25: M | E25: 1 | F25: 12 | G25: Everest 2023 | H25: 0.1 | I25: 0.2 | J25: 0.5 | K25: 0.15 | L25: 0.05 | M25: =IF(D25="L",Assumptions!C38,IF(D25="M",Assumptions!C39,IF(D25="H",Assumptions!C40,IF(D25="VH",Assumptions!C41,1)))) -> 1 | N25: =E25*F25 -> 12 | O25: =N25*M25 -> 12 | P25: Functional Consultant
B26: ERP – Financials | C26: General Ledger & Chart of Accounts | D26: H | E26: 1 | F26: 18 | G26: Forrester TEI | H26: 0.15 | I26: 0.2 | J26: 0.4 | K26: 0.2 | L26: 0.05 | M26: =IF(D26="L",Assumptions!C38,IF(D26="M",Assumptions!C39,IF(D26="H",Assumptions!C40,IF(D26="VH",Assumptions!C41,1)))) -> 1.4 | N26: =E26*F26 -> 18 | O26: =N26*M26 -> 25.2 | P26: Functional Lead
B27: ERP – Financials | C27: Accounts Payable | D27: M | E27: 1 | F27: 12 | G27: Everest 2023 | H27: 0.1 | I27: 0.2 | J27: 0.5 | K27: 0.15 | L27: 0.05 | M27: =IF(D27="L",Assumptions!C38,IF(D27="M",Assumptions!C39,IF(D27="H",Assumptions!C40,IF(D27="VH",Assumptions!C41,1)))) -> 1 | N27: =E27*F27 -> 12 | O27: =N27*M27 -> 12 | P27: Functional Consultant
B28: ERP – Financials | C28: Accounts Receivable | D28: M | E28: 1 | F28: 12 | G28: Everest 2023 | H28: 0.1 | I28: 0.2 | J28: 0.5 | K28: 0.15 | L28: 0.05 | M28: =IF(D28="L",Assumptions!C38,IF(D28="M",Assumptions!C39,IF(D28="H",Assumptions!C40,IF(D28="VH",Assumptions!C41,1)))) -> 1 | N28: =E28*F28 -> 12 | O28: =N28*M28 -> 12 | P28: Functional Consultant
B29: ERP – Financials | C29: Fixed Assets | D29: M | E29: 1 | F29: 10 | G29: Everest 2023 | H29: 0.1 | I29: 0.2 | J29: 0.5 | K29: 0.15 | L29: 0.05 | M29: =IF(D29="L",Assumptions!C38,IF(D29="M",Assumptions!C39,IF(D29="H",Assumptions!C40,IF(D29="VH",Assumptions!C41,1)))) -> 1 | N29: =E29*F29 -> 10 | O29: =N29*M29 -> 10 | P29: Functional Consultant
B30: ERP – Financials | C30: Cash Management & Banking | D30: M | E30: 1 | F30: 8 | G30: Gartner 2022 | H30: 0.1 | I30: 0.2 | J30: 0.5 | K30: 0.15 | L30: 0.05 | M30: =IF(D30="L",Assumptions!C38,IF(D30="M",Assumptions!C39,IF(D30="H",Assumptions!C40,IF(D30="VH",Assumptions!C41,1)))) -> 1 | N30: =E30*F30 -> 8 | O30: =N30*M30 -> 8 | P30: Functional Consultant
B31: ERP – Financials | C31: Intercompany & Consolidation | D31: H | E31: 3 | F31: 20 | G31: Forrester TEI | H31: 0.1 | I31: 0.2 | J31: 0.45 | K31: 0.2 | L31: 0.05 | M31: =IF(D31="L",Assumptions!C38,IF(D31="M",Assumptions!C39,IF(D31="H",Assumptions!C40,IF(D31="VH",Assumptions!C41,1)))) -> 1.4 | N31: =E31*F31 -> 60 | O31: =N31*M31 -> 84 | P31: Functional Lead
B32: ERP – Financials | C32: Tax (GTAX / Avalara Integration) | D32: H | E32: 3 | F32: 15 | G32: Forrester TEI | H32: 0.1 | I32: 0.2 | J32: 0.4 | K32: 0.25 | L32: 0.05 | M32: =IF(D32="L",Assumptions!C38,IF(D32="M",Assumptions!C39,IF(D32="H",Assumptions!C40,IF(D32="VH",Assumptions!C41,1)))) -> 1.4 | N32: =E32*F32 -> 45 | O32: =N32*M32 -> 63 | P32: Technical Lead
B33: ERP – Financials | C33: Expense Management (OIE/iExpense) | D33: L | E33: 1 | F33: 6 | G33: Everest 2023 | H33: 0.1 | I33: 0.2 | J33: 0.5 | K33: 0.15 | L33: 0.05 | M33: =IF(D33="L",Assumptions!C38,IF(D33="M",Assumptions!C39,IF(D33="H",Assumptions!C40,IF(D33="VH",Assumptions!C41,1)))) -> 0.7 | N33: =E33*F33 -> 6 | O33: =N33*M33 -> 4.2 | P33: Functional Consultant
B34: ERP – Procurement | C34: Purchasing & Sourcing | D34: M | E34: 1 | F34: 12 | G34: Everest 2023 | H34: 0.1 | I34: 0.2 | J34: 0.5 | K34: 0.15 | L34: 0.05 | M34: =IF(D34="L",Assumptions!C38,IF(D34="M",Assumptions!C39,IF(D34="H",Assumptions!C40,IF(D34="VH",Assumptions!C41,1)))) -> 1 | N34: =E34*F34 -> 12 | O34: =N34*M34 -> 12 | P34: Functional Consultant
B35: ERP – Procurement | C35: Supplier Portal & Self-Service | D35: M | E35: 1 | F35: 10 | G35: Forrester TEI | H35: 0.1 | I35: 0.2 | J35: 0.5 | K35: 0.15 | L35: 0.05 | M35: =IF(D35="L",Assumptions!C38,IF(D35="M",Assumptions!C39,IF(D35="H",Assumptions!C40,IF(D35="VH",Assumptions!C41,1)))) -> 1 | N35: =E35*F35 -> 10 | O35: =N35*M35 -> 10 | P35: Functional Consultant
B36: ERP – Procurement | C36: Contract Management | D36: M | E36: 1 | F36: 8 | G36: Everest 2023 | H36: 0.1 | I36: 0.2 | J36: 0.5 | K36: 0.15 | L36: 0.05 | M36: =IF(D36="L",Assumptions!C38,IF(D36="M",Assumptions!C39,IF(D36="H",Assumptions!C40,IF(D36="VH",Assumptions!C41,1)))) -> 1 | N36: =E36*F36 -> 8 | O36: =N36*M36 -> 8 | P36: Functional Consultant
B37: SCM | C37: Inventory Management | D37: M | E37: 1 | F37: 12 | G37: Everest 2023 | H37: 0.1 | I37: 0.2 | J37: 0.5 | K37: 0.15 | L37: 0.05 | M37: =IF(D37="L",Assumptions!C38,IF(D37="M",Assumptions!C39,IF(D37="H",Assumptions!C40,IF(D37="VH",Assumptions!C41,1)))) -> 1 | N37: =E37*F37 -> 12 | O37: =N37*M37 -> 12 | P37: Functional Lead
B38: SCM | C38: Order Management | D38: H | E38: 1 | F38: 18 | G38: Forrester TEI | H38: 0.1 | I38: 0.2 | J38: 0.45 | K38: 0.2 | L38: 0.05 | M38: =IF(D38="L",Assumptions!C38,IF(D38="M",Assumptions!C39,IF(D38="H",Assumptions!C40,IF(D38="VH",Assumptions!C41,1)))) -> 1.4 | N38: =E38*F38 -> 18 | O38: =N38*M38 -> 25.2 | P38: Functional Lead
B39: SCM | C39: Supply Chain Planning (SCP/S&OP) | D39: H | E39: 1 | F39: 22 | G39: Gartner 2022 | H39: 0.1 | I39: 0.2 | J39: 0.45 | K39: 0.2 | L39: 0.05 | M39: =IF(D39="L",Assumptions!C38,IF(D39="M",Assumptions!C39,IF(D39="H",Assumptions!C40,IF(D39="VH",Assumptions!C41,1)))) -> 1.4 | N39: =E39*F39 -> 22 | O39: =N39*M39 -> 30.8 | P39: Functional Lead
B40: SCM | C40: Manufacturing (WIP/BOM/Routing) | D40: H | E40: 1 | F40: 25 | G40: Everest 2023 | H40: 0.1 | I40: 0.2 | J40: 0.45 | K40: 0.2 | L40: 0.05 | M40: =IF(D40="L",Assumptions!C38,IF(D40="M",Assumptions!C39,IF(D40="H",Assumptions!C40,IF(D40="VH",Assumptions!C41,1)))) -> 1.4 | N40: =E40*F40 -> 25 | O40: =N40*M40 -> 35 | P40: Functional Lead
B41: SCM | C41: Quality Management | D41: M | E41: 1 | F41: 10 | G41: Everest 2023 | H41: 0.1 | I41: 0.2 | J41: 0.5 | K41: 0.15 | L41: 0.05 | M41: =IF(D41="L",Assumptions!C38,IF(D41="M",Assumptions!C39,IF(D41="H",Assumptions!C40,IF(D41="VH",Assumptions!C41,1)))) -> 1 | N41: =E41*F41 -> 10 | O41: =N41*M41 -> 10 | P41: Functional Consultant
B42: SCM | C42: Warehouse Management (WMS) | D42: H | E42: 1 | F42: 20 | G42: Gartner 2022 | H42: 0.1 | I42: 0.2 | J42: 0.45 | K42: 0.2 | L42: 0.05 | M42: =IF(D42="L",Assumptions!C38,IF(D42="M",Assumptions!C39,IF(D42="H",Assumptions!C40,IF(D42="VH",Assumptions!C41,1)))) -> 1.4 | N42: =E42*F42 -> 20 | O42: =N42*M42 -> 28 | P42: Functional Lead
B43: SCM | C43: Procurement Contracts | D43: L | E43: 1 | F43: 6 | G43: Everest 2023 | H43: 0.1 | I43: 0.2 | J43: 0.55 | K43: 0.1 | L43: 0.05 | M43: =IF(D43="L",Assumptions!C38,IF(D43="M",Assumptions!C39,IF(D43="H",Assumptions!C40,IF(D43="VH",Assumptions!C41,1)))) -> 0.7 | N43: =E43*F43 -> 6 | O43: =N43*M43 -> 4.2 | P43: Functional Consultant
...

Sheet Benchmark Library
B1: INDUSTRY BENCHMARK LIBRARY — Oracle Fusion Cloud Implementation Unit Rates
B3: EVEREST GROUP — Oracle Fusion HCM/ERP Cloud (2023 Enterprise Adoption Report)
B4: Benchmark Item | C4: Category | D4: Low | E4: High | F4: Typical | G4: Unit | H4: Context / Notes
B5: HCM Core HR setup (single country) | C5: Module Setup | D5: 10 | E5: 16 | F5: 13 | G5: Man-days | H5: Mid-Market (2,500–10,000 EE)
B6: HCM Payroll (complex fast formulas) | C6: Module Setup | D6: 18 | E6: 28 | F6: 22 | G6: Man-days | H6: Enterprise, multiple pay-groups
B7: Financials GL / CoA Design | C7: Configuration | D7: 14 | E7: 22 | F7: 18 | G7: Man-days | H7: Multi-entity, shared services
B8: AP Full Configuration | C8: Configuration | D8: 10 | E8: 14 | F8: 12 | G8: Man-days | H8: Standard 3-way match
B9: Integration – Simple (FBDI/REST batch) | C9: Integration | D9: 4 | E9: 8 | F9: 6 | G9: Man-days | H9: Per interface object
B10: Integration – Complex (real-time OIC) | C10: Integration | D10: 10 | E10: 18 | F10: 14 | G10: Man-days | H10: Bidirectional, orchestrated
B11: Data Migration – FBDI object (cleanse+load) | C11: Data Migration | D11: 3 | E11: 6 | F11: 4 | G11: Man-days | H11: Per migration object
B12: OTBI Standard Report | C12: Reporting | D12: 1 | E12: 2 | F12: 1.5 | G12: Man-days | H12: OOB subject area
B13: Custom BIP/OTBI Complex Report | C13: Reporting | D13: 4 | E13: 7 | F13: 5 | G13: Man-days | H13: With calculations, joins
B14: End-User Training (hrs/user) | C14: Training | D14: 4 | E14: 8 | F14: 6 | G14: Hours | H14: Role-based; blended delivery
B15: Hypercare Support (per module/month) | C15: Post Go-Live | D15: 5 | E15: 10 | F15: 7 | G15: Man-days | H15: Stabilisation period
B17: FORRESTER TEI — Oracle Cloud ERP/HCM Implementations (2022–2024 Composite)
B18: Benchmark Item | C18: Category | D18: Low | E18: High | F18: Typical | G18: Unit | H18: Context / Notes
B19: Programme Management overhead | C19: PM | D19: 12 | E19: 18 | F19: 15 | G19: % effort | H19: Of total delivery effort
B20: ERP Financials – full pillar | C20: Module | D20: 220 | E20: 380 | F20: 300 | G20: Man-days | H20: GL/AP/AR/FA/CM – enterprise
B21: HCM – full pillar (HR+Pay+Talent) | C21: Module | D21: 180 | E21: 320 | F21: 250 | G21: Man-days | H21: Global, multi-country payroll
B22: SCM – full pillar | C22: Module | D22: 200 | E22: 360 | F22: 280 | G22: Man-days | H22: Mfg+OMS+Planning+WMS
B23: Integration effort (% of total) | C23: Integration | D23: 15 | E23: 25 | F23: 20 | G23: % effort | H23: Typical integration ratio
B24: Data Migration (% of total) | C24: Data Migration | D24: 8 | E24: 15 | F24: 12 | G24: % effort | H24: Of total project effort
B25: Testing (% of total) | C25: Testing | D25: 15 | E25: 22 | F25: 18 | G25: % effort | H25: SIT+UAT+Perf
B26: OCM / Change (% of total) | C26: OCM | D26: 6 | E26: 12 | F26: 8 | G26: % effort | H26: Incl. comms, training
B27: Security & Role Design (enterprise) | C27: Security | D27: 15 | E27: 25 | F27: 20 | G27: Man-days | H27: RBAC design + SoD
B28: EPM Planning (EPBCS) | C28: Module | D28: 140 | E28: 240 | F28: 190 | G28: Man-days | H28: Enterprise planning + budgeting
B30: GARTNER — ERP Cloud Deployment Benchmarks (2022 Magic Quadrant Companion)
B31: Benchmark Item | C31: Category | D31: Low | E31: High | F31: Typical | G31: Unit | H31: Context / Notes
B32: Overall project duration – mid-market | C32: Timeline | D32: 10 | E32: 14 | F32: 12 | G32: Months | H32: 5–8 modules, 1–3 entities
B33: Overall project duration – enterprise | C33: Timeline | D33: 18 | E33: 30 | F33: 22 | G33: Months | H33: Full suite, multi-country
B34: Effort: Vendor PS vs SI split | C34: Resourcing | D34: 20 | E34: 30 | F34: 25 | G34: % SI | H34: Oracle PS typically 20-30%
B35: CEMLI (custom ext.) per project avg | C35: Customisation | D35: 10 | E35: 40 | F35: 20 | G35: Count | H35: Best practice: minimise
B36: Integration count – mid-market | C36: Integration | D36: 20 | E36: 40 | F36: 30 | G36: Count | H36: ERP + HCM + legacy
B37: Integration count – enterprise | C37: Integration | D37: 50 | E37: 150 | F37: 80 | G37: Count | H37: Full enterprise landscape
B38: Test cycles (SIT rounds) | C38: Testing | D38: 2 | E38: 3 | F38: 2.5 | G38: Rounds | H38: Typical SIT iterations
B39: UAT duration | C39: Testing | D39: 3 | E39: 6 | F39: 4 | G39: Weeks | H39: Business-led UAT window
B40: Cutover window | C40: Cutover | D40: 1 | E40: 3 | F40: 2 | G40: Weekends | H40: Hard cutover + parallel run
B41: Hypercare period | C41: Post Go-Live | D41: 4 | E41: 8 | F41: 6 | G41: Weeks | H41: L1/L2 hyper support
B42: Total cost of ownership – 3yr uplift | C42: Finance | D42: 120 | E42: 180 | F42: 150 | G42: % vs on-prem | H42: TCO comparison cloud vs legacy
B44: SFIA v8 / ITSM — Oracle Cloud Technical Benchmarks
...

Sheet Effort Summary
B1: CONSOLIDATED EFFORT SUMMARY — By Module & SDLC Phase
B3: A. EFFORT BY MODULE (Days — Adjusted for Complexity + Contingency)
B4: Module / Pillar | C4: Base Effort (Days) | D4: Complexity Adj. (Days) | E4: Contingency (Days) | F4: Total Effort (Days) | G4: % of Total | H4: Est. Duration (weeks) | I4: Avg FTE Required | J4: Key Roles
B5: HCM – Core HR | C5: 24 | D5: =C5*1.15 -> 27.6 | E5: =D5*Assumptions!C13/100 -> 4.692 | F5: =D5+E5 -> 32.292
B6: HCM – Payroll | C6: 24 | D6: =C6*1.15 -> 27.6 | E6: =D6*Assumptions!C13/100 -> 4.692 | F6: =D6+E6 -> 32.292
B7: HCM – Talent | C7: 24 | D7: =C7*1.15 -> 27.6 | E7: =D7*Assumptions!C13/100 -> 4.692 | F7: =D7+E7 -> 32.292
B8: HCM – Benefits | C8: 12 | D8: =C8*1.15 -> 13.8 | E8: =D8*Assumptions!C13/100 -> 2.346 | F8: =D8+E8 -> 16.146
B9: ERP – Financials | C9: 96 | D9: =C9*1.15 -> 110.4 | E9: =D9*Assumptions!C13/100 -> 18.768 | F9: =D9+E9 -> 129.168
B10: ERP – Procurement | C10: 24 | D10: =C10*1.15 -> 27.6 | E10: =D10*Assumptions!C13/100 -> 4.692 | F10: =D10+E10 -> 32.292
B11: SCM | C11: 84 | D11: =C11*1.15 -> 96.6 | E11: =D11*Assumptions!C13/100 -> 16.422 | F11: =D11+E11 -> 113.022
B12: CX – Sales | C12: 24 | D12: =C12*1.15 -> 27.6 | E12: =D12*Assumptions!C13/100 -> 4.692 | F12: =D12+E12 -> 32.292
B13: CX – Service | C13: 10 | D13: =C13*1.15 -> 11.5 | E13: =D13*Assumptions!C13/100 -> 1.955 | F13: =D13+E13 -> 13.455
B14: CX – Marketing | C14: 12 | D14: =C14*1.15 -> 13.8 | E14: =D14*Assumptions!C13/100 -> 2.346 | F14: =D14+E14 -> 16.146
B15: EPM | C15: 80 | D15: =C15*1.15 -> 92 | E15: =D15*Assumptions!C13/100 -> 15.64 | F15: =D15+E15 -> 107.64
B16: Integration | C16: 32 | D16: =C16*1.15 -> 36.8 | E16: =D16*Assumptions!C13/100 -> 6.256 | F16: =D16+E16 -> 43.056
B17: Data Migration | C17: 60 | D17: =C17*1.15 -> 69 | E17: =D17*Assumptions!C13/100 -> 11.73 | F17: =D17+E17 -> 80.73
B18: Reporting | C18: 20 | D18: =C18*1.15 -> 23 | E18: =D18*Assumptions!C13/100 -> 3.91 | F18: =D18+E18 -> 26.91
B19: Security | C19: 45 | D19: =C19*1.15 -> 51.75 | E19: =D19*Assumptions!C13/100 -> 8.7975 | F19: =D19+E19 -> 60.5475
B20: Testing & QA | C20: 100 | D20: =C20*1.15 -> 115 | E20: =D20*Assumptions!C13/100 -> 19.55 | F20: =D20+E20 -> 134.55
B21: OCM & Training | C21: 75 | D21: =C21*1.15 -> 86.25 | E21: =D21*Assumptions!C13/100 -> 14.6625 | F21: =D21+E21 -> 100.9125
B22: Programme Mgmt | C22: 48 | D22: =C22*1.15 -> 55.2 | E22: =D22*Assumptions!C13/100 -> 9.384 | F22: =D22+E22 -> 64.584
B23: TOTAL | C23: =SUM(C5:C22) -> 794 | D23: =SUM(D5:D22) -> 913.1 | E23: =SUM(E5:E22) -> 155.227 | F23: =SUM(F5:F22) -> 1068.327
B25: B. EFFORT BY SDLC PHASE
B26: SDLC Phase | C26: % Split | D26: Effort (Days) | E26: Effort (Hours) | F26: Elapsed Weeks | G26: Avg FTE
B27: Inception/Mobilise | C27: 0.05 | D27: =C27*F23 -> 53.41635 | E27: =D27*Assumptions!C12 -> 427.3308
B28: Discover & Assess | C28: 0.12 | D28: =C28*F23 -> 128.19924 | E28: =D28*Assumptions!C12 -> 1025.5939
B29: Design (Blueprint) | C29: 0.18 | D29: =C29*F23 -> 192.29886 | E29: =D29*Assumptions!C12 -> 1538.3909
B30: Build / Configure | C30: 0.28 | D30: =C30*F23 -> 299.13156 | E30: =D30*Assumptions!C12 -> 2393.0525
B31: Integration & Testing | C31: 0.17 | D31: =C31*F23 -> 181.61559 | E31: =D31*Assumptions!C12 -> 1452.9247
B32: Data Migration | C32: 0.08 | D32: =C32*F23 -> 85.46616 | E32: =D32*Assumptions!C12 -> 683.72928
B33: Training & OCM | C33: 0.06 | D33: =C33*F23 -> 64.09962 | E33: =D33*Assumptions!C12 -> 512.79696
B34: Go-Live / Cutover | C34: 0.03 | D34: =C34*F23 -> 32.04981 | E34: =D34*Assumptions!C12 -> 256.39848
B35: Post Go-Live Support | C35: 0.03 | D35: =C35*F23 -> 32.04981 | E35: =D35*Assumptions!C12 -> 256.39848

Sheet FTE & Role Plan
B1: FTE LOADING PLAN & ROLE MAPPING — Oracle Fusion Cloud Implementation
B2: Month columns assume 18-month project (adjust in Assumptions). FTE = Effort Days / (20 working days/month).
B4: A. ROLE DEFINITION & RESPONSIBILITIES
B5: Role | C5: Level | D5: Key Responsibilities | E5: Avg Daily Rate (Blended) | F5: Total Effort (Days) | G5: Peak FTE
B6: Programme Director | C6: Partner | D6: Overall programme governance, exec steering, P&L | E6: 1290 | F6: 30 | G6: 1
B7: Solution Architect | C7: Senior Manager | D7: End-to-end architecture, integration design, governance | E7: 1065 | F7: 80 | G7: 1
B8: HCM Functional Lead | C8: Senior Manager | D8: Lead HCM stream: Core HR, Payroll, Talent, Benefits | E8: 870 | F8: 150 | G8: 1
B9: Finance Functional Lead | C9: Senior Manager | D9: Lead Finance stream: GL, AP, AR, FA, Tax | E9: 870 | F9: 160 | G9: 1
B10: SCM Functional Lead | C10: Senior Manager | D10: Lead SCM: Inventory, OMS, Manufacturing, WMS | E10: 870 | F10: 140 | G10: 1
B11: Technical/Integration Lead | C11: Senior Manager | D11: OIC design, CEMLI builds, API governance | E11: 935 | F11: 120 | G11: 1
B12: Functional Consultant x3 | C12: Manager | D12: Module configuration, CRP facilitation, UAT support | E12: 696 | F12: 350 | G12: 2
B13: Functional Consultant x4 | C13: Senior Associate | D13: Config, testing, training, data migration tasks | E13: 522 | F13: 400 | G13: 3
B14: Technical Developer x2 | C14: Senior Associate | D14: CEMLI, OIC flows, BIP/OTBI reports, security roles | E14: 551 | F14: 200 | G14: 1
B15: Data Migration Specialist | C15: Manager | D15: Extract, cleanse, FBDI build, trial loads, reconciliation | E15: 638 | F15: 100 | G15: 1
B16: Change Management Lead | C16: Manager | D16: OCM strategy, comms, training design, readiness assessment | E16: 754 | F16: 80 | G16: 1
B17: Testing Lead | C17: Manager | D17: Test strategy, SIT/UAT management, defect triage | E17: 580 | F17: 90 | G17: 1
... B19: Project Manager | C19: Manager | D19: Plan, RAID, governance packs, steering reporting | E19: 812 | F19: 90 | G19: 1
B22: B. MONTHLY FTE RAMP PLAN (18-Month Programme)
B23: Role / Phase | C23: M1 | D23: M2 | E23: M3 | F23: M4 | G23: M5 | H23: M6 | I23: M7 | J23: M8 | K23: M9 | L23: M10 | M23: M11 | N23: M12 | O23: M13 | P23: M14 | Q23: M15 | R23: M16 | S23: M17 | T23: M18 | U23: Peak FTE | V23: Total Days
B24: Programme Director | C24: 1 | D24: 1 | E24: 1 | F24: 1 | G24: 1 | H24: 1 | I24: 1 | J24: 1 | K24: 1 | L24: 1 | M24: 1 | N24: 1 | O24: 1 | P24: 1 | Q24: 1 | R24: 1 | S24: 1 | T24: 1 | U24: 1 | V24: 360
B25: Solution Architect | C25: 1 | D25: 1 | E25: 2 | F25: 2 | G25: 2 | H25: 2 | I25: 1 | J25: 1 | K25: 1 | L25: 1 | M25: 1 | N25: 1 | O25: 1 | P25: 1 | U25: 2 | V25: 360
B26: HCM Functional Lead | D26: 1 | E26: 1 | F26: 2 | G26: 2 | H26: 2 | I26: 2 | J26: 1 | K26: 1 | L26: 1 | M26: 1 | U26: 2 | V26: 280
B27: Finance Functional Lead | D27: 1 | E27: 1 | F27: 2 | G27: 2 | H27: 2 | I27: 2 | J27: 1 | K27: 1 | L27: 1 | M27: 1 | U27: 2 | V27: 280
B28: SCM Functional Lead | D28: 1 | E28: 1 | F28: 2 | G28: 2 | H28: 2 | I28: 2 | J28: 1 | K28: 1 | L28: 1 | M28: 1 | U28: 2 | V28: 280
B29: Technical/Integ. Lead | E29: 1 | F29: 1 | G29: 2 | H29: 2 | I29: 2 | J29: 2 | K29: 2 | L29: 1 | M29: 1 | N29: 1 | U29: 2 | V29: 300
B30: Functional Consultants | D30: 1 | E30: 2 | F30: 3 | G30: 4 | H30: 4 | I30: 4 | J30: 3 | K30: 3 | L30: 2 | M30: 2 | N30: 1 | U30: 4 | V30: 580
B31: Technical Developers | E31: 1 | F31: 2 | G31: 2 | H31: 2 | I31: 2 | J31: 2 | K31: 1 | L31: 1 | U31: 2 | V31: 260
B32: Data Migration Specialist | E32: 1 | F32: 1 | G32: 1 | H32: 1 | I32: 2 | J32: 2 | K32: 2 | L32: 1 | M32: 1 | U32: 2 | V32: 240
B33: Change Mgmt Lead | D33: 1 | E33: 1 | F33: 1 | G33: 1 | H33: 1 | I33: 1 | J33: 1 | K33: 1 | L33: 1 | M33: 1 | N33: 1 | O33: 1 | U33: 1 | V33: 240
B34: Testing Lead | G34: 1 | H34: 1 | I34: 1 | J34: 2 | K34: 2 | L34: 2 | M34: 1 | U34: 2 | V34: 200
B35: Infrastructure Engineer | C35: 1 | D35: 1 | E35: 1 | F35: 1 | U35: 1 | V35: 80
B36: Project Manager | C36: 1 | D36: 1 | E36: 1 | F36: 1 | G36: 1 | H36: 1 | I36: 1 | J36: 1 | K36: 1 | L36: 1 | M36: 1 | N36: 1 | O36: 1 | P36: 1 | Q36: 1 | R36: 1 | S36: 1 | T36: 1 | U36: 1 | V36: 360
B37: TOTAL FTE (per month) | C37: 4 | D37: 9 | E37: 14 | F37: 19 | G37: 21 | H37: 21 | I37: 21 | J37: 18 | K37: 17 | L37: 14 | M37: 12 | N37: 6 | O37: 4 | P37: 3 | Q37: 2 | R37: 2 | S37: 2 | T37: 2

Sheet Assumptions & Risks
B1: ESTIMATION ASSUMPTIONS, EXCLUSIONS & RISK REGISTER
B3: A. STANDARD ESTIMATION ASSUMPTIONS
B4: Oracle Fusion Cloud is the confirmed target platform; no on-premise deployment | G4: Scope
B5: Effort covers System Integrator (SI) delivery only; Oracle Product Support and Client internal effort are excluded unless stated | G5: Scope
B6: All modules listed in the Assumptions tab are in scope; any additions will require re-estimation | G6: Scope
B7: Client SMEs will be available ≥40% of their time during Discover, Design, and UAT phases | G7: Access
B8: Client will provide timely access to legacy system data, current process documentation, and IT environments | G8: Access
B9: Business decisions on process design and configuration choices will be made within 5 business days of presentation | G9: Decisions
B10: Source data quality is assumed acceptable; poor data quality requiring extensive cleansing will add effort | G10: Data
B11: Number of data migration objects is as stated in Assumptions tab; additions will be change-controlled | G11: Data
B12: Integration count and complexity as stated; major undiscovered interfaces will be change-controlled | G12: Integrations
B13: Third-party system owners will provide API documentation and sandbox environments within 4 weeks of project start | G13: Integrations
B14: Oracle Cloud environments (DEV, TEST, PROD) will be provisioned by the client within 2 weeks of project kick-off | G14: Environment
B15: Client business users will actively participate in and lead UAT; SI provides facilitation and defect management only | G15: Testing
... B21: No major regulatory change during the project period; any new legislative requirements will be change-controlled | G21: Regulatory
B23: B. STANDARD EXCLUSIONS FROM THIS ESTIMATE
B24: ✗ Oracle licensing costs (SaaS subscription fees)
B25: ✗ Client internal resource costs (business SMEs, IT staff time)
B26: ✗ Third-party software licences (middleware, testing tools, BI platforms)
B27: ✗ Infrastructure / hardware costs for retained on-premise systems
B28: ✗ Business process re-engineering (BPR) beyond Oracle standard process adoption
B29: ✗ Post-hypercare ongoing AMS/managed services (separate engagement)
B30: ✗ Country-specific legal/statutory localisation beyond standard Oracle localisation packs
B31: ✗ Legacy system decommissioning and data archival
B32: ✗ Organisational restructuring or headcount change management beyond programme OCM
B33: ✗ Independent Testing/Assurance (ITA) if procured separately
B34: ✗ Oracle Primavera, Agile PLM, or other non-Fusion Cloud products
B36: C. ESTIMATION RISK REGISTER
B37: Risk Description | C37: Category | D37: Probability (H/M/L) | E37: Impact (H/M/L) | F37: Effort Adder (%) | G37: Mitigation
B38: Scope creep from undiscovered business requirements | C38: Scope | D38: H | E38: H | F38: +10% | G38: Fixed-scope SoW with change control; CRP gates
B39: Poor data quality in legacy systems requiring extensive cleanse | C39: Data | D39: H | E39: H | F39: +15% | G39: Data quality assessment in Phase 0; early profiling
B40: Client SME availability below 40% commitment | C40: Resourcing | D40: H | E40: M | F40: +10% | G40: Escalation path to Steering; contractual commitment
B41: Integration complexity higher than estimated (undiscovered APIs) | C41: Integration | D41: M | E41: H | F41: +12% | G41: Integration discovery workshop in Week 2
B42: Configuration decisions delayed beyond 5-day SLA | C42: Governance | D42: M | E42: M | F42: +8% | G42: Decision log; 48hr escalation to Programme Sponsor
B43: Regulatory change during project (tax, payroll legislation) | C43: Regulatory | D43: M | E43: H | F43: +10% | G43: Change control; buffer in payroll and tax streams
B44: Oracle Cloud quarterly update breaking custom configuration | C44: Technical | D44: M | E44: M | F44: +5% | G44: Regression test suite; Oracle release calendar monitoring
B45: Cutover complexity greater than estimated (data volumes/reconciliation) | C45: Cutover | D45: M | E45: H | F45: +12% | G45: Mock cutover rehearsal; 2 dry runs planned
B46: Key SI resources leave mid-project | C46: Resourcing | D46: L | E46: H | F46: +8% | G46: Knowledge capture; redundancy in leads; succession plan
B47: Third-party system owners unresponsive for integration testing | C47: Integration | D47: M | E47: M | F47: +10% | G47: SLA in integration agreement; early engagement
B48: Oracle environment provisioning delays (OCI setup) | C48: Environment | D48: L | E48: M | F48: +5% | G48: Cloud readiness checklist; OCI fast-track provisioning
...

Sheet Cost Model
B1: COMMERCIAL COST MODEL — Oracle Fusion Cloud Implementation
B3: A. EFFORT-TO-COST BRIDGE BY ROLE BAND
B4: Role / Band | C4: Effort (Days) | D4: Onshore Rate ($/day) | E4: Offshore Rate ($/day) | F4: Blended Rate ($/day) | G4: Onshore Cost ($) | H4: Offshore Cost ($) | I4: Total Cost ($)
B5: Programme Director | C5: 30 | D5: 2200 | E5: 900 | F5: =Assumptions!C18/100*D5+Assumptions!C19/100*E5 -> 1290 | G5: =C5*Assumptions!C18/100*D5 -> 19800 | H5: =C5*Assumptions!C19/100*E5 -> 18900 | I5: =G5+H5 -> 38700
B6: Solution Architect | C6: 80 | D6: 1800 | E6: 750 | F6: =Assumptions!C18/100*D6+Assumptions!C19/100*E6 -> 1065 | G6: =C6*Assumptions!C18/100*D6 -> 43200 | H6: =C6*Assumptions!C19/100*E6 -> 42000 | I6: =G6+H6 -> 85200
B7: HCM Functional Lead | C7: 150 | D7: 1500 | E7: 600 | F7: =Assumptions!C18/100*D7+Assumptions!C19/100*E7 -> 870 | G7: =C7*Assumptions!C18/100*D7 -> 67500 | H7: =C7*Assumptions!C19/100*E7 -> 63000 | I7: =G7+H7 -> 130500
B8: Finance Functional Lead | C8: 160 | D8: 1500 | E8: 600 | F8: =Assumptions!C18/100*D8+Assumptions!C19/100*E8 -> 870 | G8: =C8*Assumptions!C18/100*D8 -> 72000 | H8: =C8*Assumptions!C19/100*E8 -> 67200 | I8: =G8+H8 -> 139200
B9: SCM Functional Lead | C9: 140 | D9: 1500 | E9: 600 | F9: =Assumptions!C18/100*D9+Assumptions!C19/100*E9 -> 870 | G9: =C9*Assumptions!C18/100*D9 -> 63000 | H9: =C9*Assumptions!C19/100*E9 -> 58800 | I9: =G9+H9 -> 121800
B10: Technical / Integ. Lead | C10: 120 | D10: 1600 | E10: 650 | F10: =Assumptions!C18/100*D10+Assumptions!C19/100*E10 -> 935 | G10: =C10*Assumptions!C18/100*D10 -> 57600 | H10: =C10*Assumptions!C19/100*E10 -> 54600 | I10: =G10+H10 -> 112200
B11: Functional Consultants | C11: 350 | D11: 1200 | E11: 480 | F11: =Assumptions!C18/100*D11+Assumptions!C19/100*E11 -> 696 | G11: =C11*Assumptions!C18/100*D11 -> 126000 | H11: =C11*Assumptions!C19/100*E11 -> 117600 | I11: =G11+H11 -> 243600
B12: Technical Developers | C12: 200 | D12: 950 | E12: 380 | F12: =Assumptions!C18/100*D12+Assumptions!C19/100*E12 -> 551 | G12: =C12*Assumptions!C18/100*D12 -> 57000 | H12: =C12*Assumptions!C19/100*E12 -> 53200 | I12: =G12+H12 -> 110200
B13: Data Migration Specialist | C13: 100 | D13: 1100 | E13: 440 | F13: =Assumptions!C18/100*D13+Assumptions!C19/100*E13 -> 638 | G13: =C13*Assumptions!C18/100*D13 -> 33000 | H13: =C13*Assumptions!C19/100*E13 -> 30800 | I13: =G13+H13 -> 63800
B14: Change Mgmt Lead | C14: 80 | D14: 1300 | E14: 520 | F14: =Assumptions!C18/100*D14+Assumptions!C19/100*E14 -> 754 | G14: =C14*Assumptions!C18/100*D14 -> 31200 | H14: =C14*Assumptions!C19/100*E14 -> 29120 | I14: =G14+H14 -> 60320
B15: Testing Lead | C15: 90 | D15: 1000 | E15: 400 | F15: =Assumptions!C18/100*D15+Assumptions!C19/100*E15 -> 580 | G15: =C15*Assumptions!C18/100*D15 -> 27000 | H15: =C15*Assumptions!C19/100*E15 -> 25200 | I15: =G15+H15 -> 52200
B16: Infrastructure Engineer | C16: 50 | D16: 1100 | E16: 450 | F16: =Assumptions!C18/100*D16+Assumptions!C19/100*E16 -> 645 | G16: =C16*Assumptions!C18/100*D16 -> 16500 | H16: =C16*Assumptions!C19/100*E16 -> 15750 | I16: =G16+H16 -> 32250
B17: Project Manager | C17: 90 | D17: 1400 | E17: 560 | F17: =Assumptions!C18/100*D17+Assumptions!C19/100*E17 -> 812 | G17: =C17*Assumptions!C18/100*D17 -> 37800 | H17: =C17*Assumptions!C19/100*E17 -> 35280 | I17: =G17+H17 -> 73080
B19: BASE DELIVERY COST (before contingency) | I19: =SUM(I5:I17) -> 1263050
B20: CONTINGENCY (15% — Assumptions C14) | I20: =I19*Assumptions!C14/100 -> 189457.5
B21: TOTAL ESTIMATED ENGAGEMENT COST | I21: =I19+I20 -> 1452507.5
B22: MANAGEMENT RESERVE (5% — advisory only, not included above) | I22: =I21*Assumptions!C15/100 -> 72625.375
B24: B. INDICATIVE COST BY SDLC PHASE
B25: SDLC Phase | C25: % Effort | D25: Phase Cost ($) | E25: % of Total
B26: Inception/Mobilise | C26: 0.05 | D26: =C26*I21 -> 72625.375
B27: Discover & Assess | C27: 0.12 | D27: =C27*I21 -> 174300.9
B28: Design (Blueprint) | C28: 0.18 | D28: =C28*I21 -> 261451.35
B29: Build / Configure | C29: 0.28 | D29: =C29*I21 -> 406702.1
B30: Integration & Testing | C30: 0.17 | D30: =C30*I21 -> 246926.27
B31: Data Migration | C31: 0.08 | D31: =C31*I21 -> 116200.6
B32: Training & OCM | C32: 0.06 | D32: =C32*I21 -> 87150.45
B33: Go-Live / Cutover | C33: 0.03 | D33: =C33*I21 -> 43575.225
B34: Post Go-Live Support | C34: 0.03 | D34: =C34*I21 -> 43575.225
