Workbook

Sheet Cover
B1: ORACLE FUSION CLOUD — DETAILED IMPLEMENTATION ESTIMATOR
B2: Bottom-Up Effort Estimation: Configuration · Customisation · Data Migration · SDLC Phase View
B4: ▶ ESTIMATE TYPE SELECTOR
B5: SELECT ESTIMATE TYPE → Enter 'H' for High-Level | 'D' for Detailed H = Use the Oracle Fusion Implementation Estimator (separate workbook — module-level, benchmark-driven) D = Use this workbook — bottom-up, activity-level breakdown by Config / Customisation / Data Migration + UT
B6: Estimate Type (H / D) | C6: D
B7: → Routing | C7: =IF(C6="D","✔ You are in the right workbook — proceed with Detailed Estimation below",IF(C6="H","→ Use the High-Level Estimator (Oracle_Fusion_Estimator.xlsx)","⚠ Enter H or D")) -> ✔ You are in the right workbook — proceed with Detailed Estimation below
B9: PROJECT METADATA
B10: Client / Engagement | C10: <<Enter Name>>
B11: Oracle Modules in Scope | C11: <<e.g. HCM, ERP, SCM, EPM>>
B12: No. of Legal Entities | C12: 3
B13: Industry Vertical | C13: <<e.g. Manufacturing>>
B14: Estimation Basis | C14: Bottom-Up Detailed (Activity Level)
B15: Prepared By | C15: <<Name>>
B16: Date | C16: <<DD-MMM-YYYY>>
B17: Version | C17: v1.0
B19: WORKBOOK TAB GUIDE
B20: Cover | C20: This sheet — project metadata + estimate type selector | F20: Input
B21: Assumptions | C21: Global levers: rates, working days, contingency, UT ratios | F21: Input
B22: Config Estimator | C22: Bottom-up config effort: task × complexity × volume per module | F22: Input+Calc
B23: Custom Estimator | C23: CEMLI / extension effort: object × type × Dev + UT days | F23: Input+Calc
B24: Data Migration Est. | C24: Migration object effort: extract + cleanse + load + UT | F24: Input+Calc
B25: SDLC Phase View | C25: Cross-pillar effort rolled up by SDLC phase across all three streams | F25: Output
B26: Role & FTE Summary | C26: Effort by role, FTE loading, peak headcount | F26: Output
B27: Cost Summary | C27: Total cost = effort × blended rates + contingency | F27: Output

Sheet Assumptions
B1: GLOBAL ASSUMPTIONS & RATE CARD
B2: All amber cells are inputs. Change here; all estimator sheets auto-update.
B4: A. WORKING CALENDAR & CONTINGENCY
B5: Parameter | C5: Value | D5: Unit | E5: Min | F5: Max | G5: Note
B6: Working Hours per Day | C6: 8 | D6: hrs | E6: 7 | F6: 9 | G6: Standard billing day
B7: Working Days per Month | C7: 20 | D7: days | E7: 18 | F7: 22 | G7: Adjust for regional holidays
B8: Contingency % | C8: 15 | D8: % | E8: 10 | F8: 25 | G8: PMI / Oracle programme standard
B9: Management Reserve % | C9: 5 | D9: % | E9: 3 | F9: 10 | G9: Programme buffer — advisory
B10: Onshore % | C10: 30 | D10: % | E10: 0 | F10: 100 | G10: Delivery model split
B11: Offshore % | C11: 70 | D11: % | E11: 0 | F11: 100 | G11: Should sum to 100 with Onshore
B12: UT % of Dev Effort (Config) | C12: 20 | D12: % | E12: 15 | F12: 30 | G12: Unit test as % of config build effort
B13: UT % of Dev Effort (Custom) | C13: 30 | D13: % | E13: 25 | F13: 40 | G13: Unit test as % of CEMLI dev effort
B14: UT % of Dev Effort (DataMig) | C14: 25 | D14: % | E14: 20 | F14: 35 | G14: Reconciliation/UT as % of migration effort
B15: Peer Review % (Custom only) | C15: 10 | D15: % | E15: 5 | F15: 15 | G15: Code review overhead on custom dev
B17: B. RATE CARD — BLENDED DAILY RATES (USD)
B18: Role / Band | C18: Onshore $/day | D18: Offshore $/day | E18: Blended $/day | F18: Level | G18: Typical Engagement %
B19: Programme Director | C19: 2200 | D19: 900 | E19: =Assumptions!C10/100*C19+Assumptions!C11/100*D19 -> 1290 | F19: Partner/Director | G19: 3%
B20: Solution Architect | C20: 1800 | D20: 750 | E20: =Assumptions!C10/100*C20+Assumptions!C11/100*D20 -> 1065 | F20: Senior Manager | G20: 5%
B21: Functional Lead (per module) | C21: 1500 | D21: 600 | E21: =Assumptions!C10/100*C21+Assumptions!C11/100*D21 -> 870 | F21: Senior Manager | G21: 12%
B22: Technical / Integration Lead | C22: 1600 | D22: 650 | E22: =Assumptions!C10/100*C22+Assumptions!C11/100*D22 -> 935 | F22: Senior Manager | G22: 8%
B23: Functional Consultant Sr. | C23: 1200 | D23: 480 | E23: =Assumptions!C10/100*C23+Assumptions!C11/100*D23 -> 696 | F23: Manager | G23: 20%
B24: Functional Consultant Mid | C24: 900 | D24: 360 | E24: =Assumptions!C10/100*C24+Assumptions!C11/100*D24 -> 522 | F24: Senior Associate | G24: 18%
B25: ABAP / OIC Developer Sr. | C25: 1000 | D25: 400 | E25: =Assumptions!C10/100*C25+Assumptions!C11/100*D25 -> 580 | F25: Manager | G25: 8%
B26: ABAP / OIC Developer Mid | C26: 800 | D26: 320 | E26: =Assumptions!C10/100*C26+Assumptions!C11/100*D26 -> 464 | F26: Senior Associate | G26: 7%
B27: Data Migration Specialist | C27: 1100 | D27: 440 | E27: =Assumptions!C10/100*C27+Assumptions!C11/100*D27 -> 638 | F27: Manager | G27: 7%
B28: Change Mgmt / OCM Lead | C28: 1300 | D28: 520 | E28: =Assumptions!C10/100*C28+Assumptions!C11/100*D28 -> 754 | F28: Manager | G28: 5%
B29: Testing Lead / QA | C29: 1000 | D29: 400 | E29: =Assumptions!C10/100*C29+Assumptions!C11/100*D29 -> 580 | F29: Manager | G29: 4%
B30: Project Manager | C30: 1400 | D30: 560 | E30: =Assumptions!C10/100*C30+Assumptions!C11/100*D30 -> 812 | F30: Manager | G30: 3%
B32: C. COMPLEXITY MULTIPLIERS (editable)
B33: Level | C33: Code | D33: Multiplier | E33: Config | F33: Selection Criteria | G33: Examples (Config | Custom | Data Migration)
B34: Low | C34: L | D34: 0.7 | E34: 0.7 | F34: • OOB / standard Oracle functionality; minimal configuration beyond defaults • Single legal entity or business unit; no country-specific localisation • Processes closely match Oracle standard; no workarounds or process redesign • Standard approval workflow (1–2 levels); standard RBAC roles sufficient • Source data is clean, well-structured, available in compatible format • Integration is one-way batch/file-based (SFTP/FTP); no transformation logic | G34: CONFIG: › Single-country absence plans & holiday calendars › Standard expense policy with OOB approval CUSTOM: › One-way batch SFTP integration (file-based) › Standard OTBI report using a single subject area DATA MIG: › Reference data (departments, grades, jobs) — clean single source › Supplier master from single ERP, no duplicates, standard fields
B35: Medium | C35: M | D35: 1 | E35: 1 | F35: • Some configuration beyond OOB; guided by Oracle best practice • 2–5 legal entities or business units sharing common structures • Minor process deviations handled via Oracle flexfields or lookups • Standard multi-level approval workflow (2–3 levels); standard security model • Source data requires moderate cleansing; mostly 1-to-1 field mapping • Standard REST/SOAP API integration; moderate transformation logic | G35: CONFIG: › Multi-entity GL with intercompany accounting (3 entities) › AP invoice approval with 3-level BPM workflow CUSTOM: › OIC REST API integration (inbound/outbound, moderate mapping) › OTBI report across 2 subject areas with calculated measures DATA MIG: › Employee master from a single HR system with standard fields › Open AP invoices from a structured ERP with known schema
B36: High | C36: H | D36: 1.4 | E36: 1.5 | F36: • Significant complexity; multiple exceptions to OOB process • 6–15 legal entities, multi-country, or cross-pillar dependencies • Legislative or regulatory requirements driving non-standard configuration • Complex multi-level approval hierarchies; data security policy design • Source data is poor quality, fragmented across systems, or unstructured • Real-time or bidirectional integration; event-driven or orchestrated flows | G36: CONFIG: › Multi-country payroll with country-specific tax localisations (3+ countries) › WMS warehouse layout with advanced picking, putaway & replenishment rules CUSTOM: › Bidirectional real-time OIC integration with complex transformation logic › Custom payroll Fast Formula with tax override and conditional logic DATA MIG: › Employee data from 3+ HR systems with conflicting schemas › Fixed assets with full depreciation history and NBV reconciliation
B37: Very High | C37: VH | D37: 1.9 | E37: 2 | F37: • Heavily customised or non-standard process; Oracle OOB not fit for purpose • 15+ legal entities, global rollout, or highly regulated (BFSI, Pharma, Defence) • High CEMLI dependency; multiple custom extensions interacting with each other • Real-time multi-system orchestration with complex event handling and retry logic • Legacy data with no clear mapping, large volumes, or critical statutory reconciliation • Concurrent go-live across multiple countries or business units in a single cutover | G37: CONFIG: › Global payroll across 10+ countries with unique legislation per country › Holding company consolidation with complex minority interest & FX elimination CUSTOM: › ODA chatbot with NLP + multi-system backend orchestration › Multi-system integration hub (ERP + HCM + CRM + 3PL + Banking) DATA MIG: › Legacy COBOL mainframe data with reverse-engineered schema › Multi-country payroll balances with local statutory year-end carryforward

Sheet Config Estimator
B1: CONFIGURATION EFFORT ESTIMATOR
B2: Activity-level config effort with Dev Days + Unit Test Days split | Amber = input | Green = calculated
B4: AMBER = Input | D4: GREEN = Calculated | F4: BLUE = Formula | H4: CX: L=Low M=Med H=High VH=VHigh
B6: Module / Pillar | C6: Configuration Task / Activity | D6: Complexity (L/M/H/VH) | E6: Volume (Count) | F6: Unit Dev Days (OOB) | G6: Benchmark Source | H6: Complexity Multiplier | I6: Base Dev Days | J6: Unit Test Days (UT%) | K6: Total Config Effort (Days) | L6: SDLC: Build % split | M6: Primary Role
B7: ▼ COMPLEXITY GUIDE — Configuration activities (Column D)
B8: Select the code that best describes the majority of the work in this row. When in doubt between two levels, always choose the higher one and document your rationale. Multipliers are applied automatically from the Assumptions tab.
B9: Level (Code) | E9: Selection Criteria | M9: Typical Example for this Sheet
B10: Low (L) ×0.7× | E10: • OOB / standard Oracle functionality; minimal configuration beyond defaults • Single legal entity or business unit; no country-specific localisation • Processes closely match Oracle standard; no workarounds or process redesign • Standard approval workflow (1–2 levels); standard RBAC roles sufficient • Source data is clean, well-structured, available in compatible format • Integration is one-way batch/file-based (SFTP/FTP); no transformation logic | M10: › Single-country absence plans & holiday calendars › Standard expense policy with OOB approval › Item category setup with standard attributes
B11: Medium (M) ×1.0× | E11: • Some configuration beyond OOB; guided by Oracle best practice • 2–5 legal entities or business units sharing common structures • Minor process deviations handled via Oracle flexfields or lookups • Standard multi-level approval workflow (2–3 levels); standard security model • Source data requires moderate cleansing; mostly 1-to-1 field mapping • Standard REST/SOAP API integration; moderate transformation logic | M11: › Multi-entity GL with intercompany accounting (3 entities) › AP invoice approval with 3-level BPM workflow › Payroll element setup for a single-country payroll
B12: High (H) ×1.4× | E12: • Significant complexity; multiple exceptions to OOB process • 6–15 legal entities, multi-country, or cross-pillar dependencies • Legislative or regulatory requirements driving non-standard configuration • Complex multi-level approval hierarchies; data security policy design • Source data is poor quality, fragmented across systems, or unstructured • Real-time or bidirectional integration; event-driven or orchestrated flows | M12: › Multi-country payroll with country-specific tax localisations (3+ countries) › WMS warehouse layout with advanced picking, putaway & replenishment rules › Security RBAC design with SoD conflict identification and remediation
B13: Very High (VH) ×2.0× | E13: • Heavily customised or non-standard process; Oracle OOB not fit for purpose • 15+ legal entities, global rollout, or highly regulated (BFSI, Pharma, Defence) • High CEMLI dependency; multiple custom extensions interacting with each other • Real-time multi-system orchestration with complex event handling and retry logic • Legacy data with no clear mapping, large volumes, or critical statutory reconciliation • Concurrent go-live across multiple countries or business units in a single cutover | M13: › Global payroll across 10+ countries with unique legislation per country › Holding company consolidation with complex minority interest & FX elimination › Manufacturing with multi-level BOM, shop floor control, and IoT sensor integration
B15: HCM – Core HR | C15: Enterprise Structures setup (BU, LE, Divisions) | D15: M | E15: 1 | F15: 5 | G15: Everest 2023 | H15: =IF(D15="L",Assumptions!D34,IF(D15="M",Assumptions!D35,IF(D15="H",Assumptions!D36,IF(D15="VH",Assumptions!D37,1)))) -> 1 | I15: =E15*F15*H15 -> 5 | J15: =I15*Assumptions!C12/100 -> 1 | K15: =I15+J15 -> 6 | L15: 65% | M15: Functional Lead
C16: Reference Data: Grades, Grade Ladders, Job Families | D16: M | E16: 1 | F16: 4 | G16: Everest 2023 | H16: =IF(D16="L",Assumptions!D34,IF(D16="M",Assumptions!D35,IF(D16="H",Assumptions!D36,IF(D16="VH",Assumptions!D37,1)))) -> 1 | I16: =E16*F16*H16 -> 4 | J16: =I16*Assumptions!C12/100 -> 0.8 | K16: =I16+J16 -> 4.8 | L16: 65% | M16: Functional Consultant
C17: Position Management configuration | D17: M | E17: 1 | F17: 4 | G17: Everest 2023 | H17: =IF(D17="L",Assumptions!D34,IF(D17="M",Assumptions!D35,IF(D17="H",Assumptions!D36,IF(D17="VH",Assumptions!D37,1)))) -> 1 | I17: =E17*F17*H17 -> 4 | J17: =I17*Assumptions!C12/100 -> 0.8 | K17: =I17+J17 -> 4.8 | L17: 65% | M17: Functional Consultant
C18: Assignment & Employment Model setup | D18: M | E18: 1 | F18: 5 | G18: Everest 2023 | H18: =IF(D18="L",Assumptions!D34,IF(D18="M",Assumptions!D35,IF(D18="H",Assumptions!D36,IF(D18="VH",Assumptions!D37,1)))) -> 1 | I18: =E18*F18*H18 -> 5 | J18: =I18*Assumptions!C12/100 -> 1 | K18: =I18+J18 -> 6 | L18: 65% | M18: Functional Lead
C19: Work Schedules & Holiday Calendars | D19: L | E19: 1 | F19: 3 | G19: Everest 2023 | H19: =IF(D19="L",Assumptions!D34,IF(D19="M",Assumptions!D35,IF(D19="H",Assumptions!D36,IF(D19="VH",Assumptions!D37,1)))) -> 0.7 | I19: =E19*F19*H19 -> 2.1 | J19: =I19*Assumptions!C12/100 -> 0.42 | K19: =I19+J19 -> 2.52 | L19: 65% | M19: Functional Consultant
C20: Absence Plans & Eligibility Rules | D20: M | E20: 1 | F20: 6 | G20: Forrester TEI | H20: =IF(D20="L",Assumptions!D34,IF(D20="M",Assumptions!D35,IF(D20="H",Assumptions!D36,IF(D20="VH",Assumptions!D37,1)))) -> 1 | I20: =E20*F20*H20 -> 6 | J20: =I20*Assumptions!C12/100 -> 1.2 | K20: =I20+J20 -> 7.2 | L20: 65% | M20: Functional Consultant
C21: Document Records & DFF setup | D21: L | E21: 1 | F21: 3 | G21: Everest 2023 | H21: =IF(D21="L",Assumptions!D34,IF(D21="M",Assumptions!D35,IF(D21="H",Assumptions!D36,IF(D21="VH",Assumptions!D37,1)))) -> 0.7 | I21: =E21*F21*H21 -> 2.1 | J21: =I21*Assumptions!C12/100 -> 0.42 | K21: =I21+J21 -> 2.52 | L21: 65% | M21: Functional Consultant
B22: HCM – Payroll | C22: Payroll Definitions & Pay Frequencies | D22: M | E22: 1 | F22: 4 | G22: Everest 2023 | H22: =IF(D22="L",Assumptions!D34,IF(D22="M",Assumptions!D35,IF(D22="H",Assumptions!D36,IF(D22="VH",Assumptions!D37,1)))) -> 1 | I22: =E22*F22*H22 -> 4 | J22: =I22*Assumptions!C12/100 -> 0.8 | K22: =I22+J22 -> 4.8 | L22: 65% | M22: Functional Lead
C23: Earnings & Deduction Elements setup | D23: H | E23: 1 | F23: 10 | G23: Everest 2023 | H23: =IF(D23="L",Assumptions!D34,IF(D23="M",Assumptions!D35,IF(D23="H",Assumptions!D36,IF(D23="VH",Assumptions!D37,1)))) -> 1.4 | I23: =E23*F23*H23 -> 14 | J23: =I23*Assumptions!C12/100 -> 2.8 | K23: =I23+J23 -> 16.8 | L23: 65% | M23: Functional Lead
C24: Fast Formula development (per formula group) | D24: H | E24: 5 | F24: 4 | G24: Everest 2023 | H24: =IF(D24="L",Assumptions!D34,IF(D24="M",Assumptions!D35,IF(D24="H",Assumptions!D36,IF(D24="VH",Assumptions!D37,1)))) -> 1.4 | I24: =E24*F24*H24 -> 28 | J24: =I24*Assumptions!C12/100 -> 5.6 | K24: =I24+J24 -> 33.6 | L24: 65% | M24: Technical Developer
C25: Payroll Costing configuration | D25: H | E25: 1 | F25: 6 | G25: Forrester TEI | H25: =IF(D25="L",Assumptions!D34,IF(D25="M",Assumptions!D35,IF(D25="H",Assumptions!D36,IF(D25="VH",Assumptions!D37,1)))) -> 1.4 | I25: =E25*F25*H25 -> 8.4 | J25: =I25*Assumptions!C12/100 -> 1.68 | K25: =I25+J25 -> 10.08 | L25: 65% | M25: Functional Lead
C26: Tax Localisation per country | D26: H | E26: 3 | F26: 8 | G26: Gartner 2022 | H26: =IF(D26="L",Assumptions!D34,IF(D26="M",Assumptions!D35,IF(D26="H",Assumptions!D36,IF(D26="VH",Assumptions!D37,1)))) -> 1.4 | I26: =E26*F26*H26 -> 33.6 | J26: =I26*Assumptions!C12/100 -> 6.72 | K26: =I26+J26 -> 40.32 | L26: 65% | M26: Functional Lead
B27: HCM – Talent | C27: Recruiting: Requisition & Offer configuration | D27: M | E27: 1 | F27: 5 | G27: Forrester TEI | H27: =IF(D27="L",Assumptions!D34,IF(D27="M",Assumptions!D35,IF(D27="H",Assumptions!D36,IF(D27="VH",Assumptions!D37,1)))) -> 1 | I27: =E27*F27*H27 -> 5 | J27: =I27*Assumptions!C12/100 -> 1 | K27: =I27+J27 -> 6 | L27: 65% | M27: Functional Consultant
C28: Performance Template & Rating Model setup | D28: M | E28: 1 | F28: 5 | G28: Everest 2023 | H28: =IF(D28="L",Assumptions!D34,IF(D28="M",Assumptions!D35,IF(D28="H",Assumptions!D36,IF(D28="VH",Assumptions!D37,1)))) -> 1 | I28: =E28*F28*H28 -> 5 | J28: =I28*Assumptions!C12/100 -> 1 | K28: =I28+J28 -> 6 | L28: 65% | M28: Functional Consultant
C29: Goal Management & Library configuration | D29: L | E29: 1 | F29: 3 | G29: Everest 2023 | H29: =IF(D29="L",Assumptions!D34,IF(D29="M",Assumptions!D35,IF(D29="H",Assumptions!D36,IF(D29="VH",Assumptions!D37,1)))) -> 0.7 | I29: =E29*F29*H29 -> 2.1 | J29: =I29*Assumptions!C12/100 -> 0.42 | K29: =I29+J29 -> 2.52 | L29: 65% | M29: Functional Consultant
B30: HCM – Benefits | C30: Benefit Plans, Options & Coverage configuration | D30: M | E30: 1 | F30: 8 | G30: Everest 2023 | H30: =IF(D30="L",Assumptions!D34,IF(D30="M",Assumptions!D35,IF(D30="H",Assumptions!D36,IF(D30="VH",Assumptions!D37,1)))) -> 1 | I30: =E30*F30*H30 -> 8 | J30: =I30*Assumptions!C12/100 -> 1.6 | K30: =I30+J30 -> 9.6 | L30: 65% | M30: Functional Consultant
C31: Eligibility Profiles setup | D31: M | E31: 1 | F31: 4 | G31: Everest 2023 | H31: =IF(D31="L",Assumptions!D34,IF(D31="M",Assumptions!D35,IF(D31="H",Assumptions!D36,IF(D31="VH",Assumptions!D37,1)))) -> 1 | I31: =E31*F31*H31 -> 4 | J31: =I31*Assumptions!C12/100 -> 0.8 | K31: =I31+J31 -> 4.8 | L31: 65% | M31: Functional Consultant
B32: ERP – GL | C32: Chart of Accounts design (segments & values) | D32: H | E32: 1 | F32: 10 | G32: Forrester TEI | H32: =IF(D32="L",Assumptions!D34,IF(D32="M",Assumptions!D35,IF(D32="H",Assumptions!D36,IF(D32="VH",Assumptions!D37,1)))) -> 1.4 | I32: =E32*F32*H32 -> 14 | J32: =I32*Assumptions!C12/100 -> 2.8 | K32: =I32+J32 -> 16.8 | L32: 65% | M32: Functional Lead
C33: Ledger & Accounting Calendar setup | D33: M | E33: 1 | F33: 5 | G33: Everest 2023 | H33: =IF(D33="L",Assumptions!D34,IF(D33="M",Assumptions!D35,IF(D33="H",Assumptions!D36,IF(D33="VH",Assumptions!D37,1)))) -> 1 | I33: =E33*F33*H33 -> 5 | J33: =I33*Assumptions!C12/100 -> 1 | K33: =I33+J33 -> 6 | L33: 65% | M33: Functional Lead
C34: Intercompany Accounting configuration | D34: H | E34: 3 | F34: 6 | G34: Forrester TEI | H34: =IF(D34="L",Assumptions!D34,IF(D34="M",Assumptions!D35,IF(D34="H",Assumptions!D36,IF(D34="VH",Assumptions!D37,1)))) -> 1.4 | I34: =E34*F34*H34 -> 25.2 | J34: =I34*Assumptions!C12/100 -> 5.04 | K34: =I34+J34 -> 30.24 | L34: 65% | M34: Functional Lead
C35: Period Close procedures & Subledger Accounting | D35: M | E35: 1 | F35: 6 | G35: Everest 2023 | H35: =IF(D35="L",Assumptions!D34,IF(D35="M",Assumptions!D35,IF(D35="H",Assumptions!D36,IF(D35="VH",Assumptions!D37,1)))) -> 1 | I35: =E35*F35*H35 -> 6 | J35: =I35*Assumptions!C12/100 -> 1.2 | K35: =I35+J35 -> 7.2 | L35: 65% | M35: Functional Lead
B36: ERP – AP | C36: Supplier Setup: Sites, Banks, Payment Terms | D36: M | E36: 1 | F36: 5 | G36: Everest 2023 | H36: =IF(D36="L",Assumptions!D34,IF(D36="M",Assumptions!D35,IF(D36="H",Assumptions!D36,IF(D36="VH",Assumptions!D37,1)))) -> 1 | I36: =E36*F36*H36 -> 5 | J36: =I36*Assumptions!C12/100 -> 1 | K36: =I36+J36 -> 6 | L36: 65% | M36: Functional Consultant
C37: Invoice Processing & Approval Workflow | D37: M | E37: 1 | F37: 5 | G37: Everest 2023 | H37: =IF(D37="L",Assumptions!D34,IF(D37="M",Assumptions!D35,IF(D37="H",Assumptions!D36,IF(D37="VH",Assumptions!D37,1)))) -> 1 | I37: =E37*F37*H37 -> 5 | J37: =I37*Assumptions!C12/100 -> 1 | K37: =I37+J37 -> 6 | L37: 65% | M37: Functional Consultant
C38: Payment Templates & Bank configuration | D38: M | E38: 1 | F38: 5 | G38: Everest 2023 | H38: =IF(D34="L",Assumptions!D34,IF(D34="M",Assumptions!D35,IF(D34="H",Assumptions!D36,IF(D34="VH",Assumptions!D37,1)))) -> 1.4 | I38: =E38*F38*H38 -> 7 | J38: =I38*Assumptions!C12/100 -> 1.4 | K38: =I38+J38 -> 8.4 | L38: 65% | M38: Functional Consultant
B39: ERP – AR | C39: Customer Setup & Credit Management | D39: M | E39: 1 | F39: 4 | G39: Everest 2023 | H39: =IF(D35="L",Assumptions!D34,IF(D35="M",Assumptions!D35,IF(D35="H",Assumptions!D36,IF(D35="VH",Assumptions!D37,1)))) -> 1 | I39: =E39*F39*H39 -> 4 | J39: =I39*Assumptions!C12/100 -> 0.8 | K39: =I39+J39 -> 4.8 | L39: 65% | M39: Functional Consultant
C40: Receipt Methods & Lockbox configuration | D40: M | E40: 1 | F40: 4 | G40: Everest 2023 | H40: =IF(D36="L",Assumptions!D34,IF(D36="M",Assumptions!D35,IF(D36="H",Assumptions!D36,IF(D36="VH",Assumptions!D37,1)))) -> 1 | I40: =E40*F40*H40 -> 4 | J40: =I40*Assumptions!C12/100 -> 0.8 | K40: =I40+J40 -> 4.8 | L40: 65% | M40: Functional Consultant
C41: Revenue Recognition rules setup | D41: H | E41: 1 | F41: 7 | G41: Forrester TEI | H41: =IF(D37="L",Assumptions!D34,IF(D37="M",Assumptions!D35,IF(D37="H",Assumptions!D36,IF(D37="VH",Assumptions!D37,1)))) -> 1 | I41: =E41*F41*H41 -> 7 | J41: =I41*Assumptions!C12/100 -> 1.4 | K41: =I41+J41 -> 8.4 | L41: 65% | M41: Functional Lead
B42: ERP – FA | C42: Asset Books, Categories & Depreciation Methods | D42: M | E42: 1 | F42: 7 | G42: Everest 2023 | H42: =IF(D42="L",Assumptions!D34,IF(D42="M",Assumptions!D35,IF(D42="H",Assumptions!D36,IF(D42="VH",Assumptions!D37,1)))) -> 1 | I42: =E42*F42*H42 -> 7 | J42: =I42*Assumptions!C12/100 -> 1.4 | K42: =I42+J42 -> 8.4 | L42: 65% | M42: Functional Consultant
C43: Lease Accounting (ASC842/IFRS16) | D43: H | E43: 1 | F43: 8 | G43: Gartner 2022 | H43: =IF(D43="L",Assumptions!D34,IF(D43="M",Assumptions!D35,IF(D43="H",Assumptions!D36,IF(D43="VH",Assumptions!D37,1)))) -> 1.4 | I43: =E43*F43*H43 -> 11.2 | J43: =I43*Assumptions!C12/100 -> 2.24 | K43: =I43+J43 -> 13.44 | L43: 65% | M43: Functional Lead
...

Sheet Custom Estimator
B1: CUSTOMISATION (CEMLI) EFFORT ESTIMATOR
B2: Bottom-up CEMLI effort: Dev Days + Unit Test + Peer Review split | Amber = input | Green = calculated
B4: UT Days = Dev Days × UT% (Assumptions C8) | Peer Review = Dev Days × Review% (Assumptions C10) | Total = Dev + UT + Review | Complexity multiplier from Assumptions Section C (col E = Custom)
B6: Module | C6: Extension Name / Description | D6: Extension Type | E6: CX (L/M/H/VH) | F6: Qty | G6: Unit Dev Days | H6: CX Multiplier | I6: Base Dev Days | J6: UT Days (UT%) | K6: Peer Rev Days | L6: Total Effort(Days) | M6: Benchmark | N6: Primary Role
B7: ▼ COMPLEXITY GUIDE — CEMLI / Extension activities (Column E)
B8: Select the code that best describes the majority of the work in this row. When in doubt between two levels, always choose the higher one and document your rationale. Multipliers are applied automatically from the Assumptions tab.
B9: Level (Code) | E9: Selection Criteria | N9: Typical Example for this Sheet
B10: Low (L) ×0.8× | E10: • OOB / standard Oracle functionality; minimal configuration beyond defaults • Single legal entity or business unit; no country-specific localisation • Processes closely match Oracle standard; no workarounds or process redesign • Standard approval workflow (1–2 levels); standard RBAC roles sufficient • Source data is clean, well-structured, available in compatible format • Integration is one-way batch/file-based (SFTP/FTP); no transformation logic | N10: › One-way batch SFTP integration (file-based) › Standard OTBI report using a single subject area › Simple page personalisation (hide/show fields)
B11: Medium (M) ×1.0× | E11: • Some configuration beyond OOB; guided by Oracle best practice • 2–5 legal entities or business units sharing common structures • Minor process deviations handled via Oracle flexfields or lookups • Standard multi-level approval workflow (2–3 levels); standard security model • Source data requires moderate cleansing; mostly 1-to-1 field mapping • Standard REST/SOAP API integration; moderate transformation logic | N11: › OIC REST API integration (inbound/outbound, moderate mapping) › OTBI report across 2 subject areas with calculated measures › BPM workflow extension with conditional routing
B12: High (H) ×1.5× | E12: • Significant complexity; multiple exceptions to OOB process • 6–15 legal entities, multi-country, or cross-pillar dependencies • Legislative or regulatory requirements driving non-standard configuration • Complex multi-level approval hierarchies; data security policy design • Source data is poor quality, fragmented across systems, or unstructured • Real-time or bidirectional integration; event-driven or orchestrated flows | N12: › Bidirectional real-time OIC integration with complex transformation logic › Custom payroll Fast Formula with tax override and conditional logic › OAC dashboard with cross-pillar KPIs and multi-source calculated metrics
B13: Very High (VH) ×1.9× | E13: • Heavily customised or non-standard process; Oracle OOB not fit for purpose • 15+ legal entities, global rollout, or highly regulated (BFSI, Pharma, Defence) • High CEMLI dependency; multiple custom extensions interacting with each other • Real-time multi-system orchestration with complex event handling and retry logic • Legacy data with no clear mapping, large volumes, or critical statutory reconciliation • Concurrent go-live across multiple countries or business units in a single cutover | N13: › ODA chatbot with NLP + multi-system backend orchestration › Multi-system integration hub (ERP + HCM + CRM + 3PL + Banking) › Custom statutory report replacing a government submission format
B15: HCM – Payroll | C15: Custom Fast Formula — Tax Override | D15: Formula | E15: H | F15: 3 | G15: 5 | H15: =IF(E15="L",Assumptions!E34,IF(E15="M",Assumptions!E35,IF(E15="H",Assumptions!E36,IF(E15="VH",Assumptions!E37,1)))) -> 1.5 | I15: =F15*G15*H15 -> 22.5 | J15: =I15*Assumptions!C13/100 -> 6.75 | K15: =I15*Assumptions!C15/100 -> 2.25 | L15: =I15+J15+K15 -> 31.5 | M15: Everest 2023 | N15: Technical Developer
C16: Custom Payslip Layout (BI Publisher) | D16: BI Publisher | E16: M | F16: 2 | G16: 6 | H16: =IF(E16="L",Assumptions!E34,IF(E16="M",Assumptions!E35,IF(E16="H",Assumptions!E36,IF(E16="VH",Assumptions!E37,1)))) -> 1 | I16: =F16*G16*H16 -> 12 | J16: =I16*Assumptions!C13/100 -> 3.6 | K16: =I16*Assumptions!C15/100 -> 1.2 | L16: =I16+J16+K16 -> 16.8 | M16: Everest 2023 | N16: Technical Developer
B17: HCM – Core HR | C17: Person Address Validation Extension | D17: Page Ext (VB) | E17: M | F17: 2 | G17: 4 | H17: =IF(E17="L",Assumptions!E34,IF(E17="M",Assumptions!E35,IF(E17="H",Assumptions!E36,IF(E17="VH",Assumptions!E37,1)))) -> 1 | I17: =F17*G17*H17 -> 8 | J17: =I17*Assumptions!C13/100 -> 2.4 | K17: =I17*Assumptions!C15/100 -> 0.8 | L17: =I17+J17+K17 -> 11.2 | M17: Everest 2023 | N17: Technical Developer
B18: HCM – Talent | C18: Custom Offer Letter Template | D18: BI Publisher | E18: L | F18: 2 | G18: 4 | H18: =IF(E18="L",Assumptions!E34,IF(E18="M",Assumptions!E35,IF(E18="H",Assumptions!E36,IF(E18="VH",Assumptions!E37,1)))) -> 0.7 | I18: =F18*G18*H18 -> 5.6 | J18: =I18*Assumptions!C13/100 -> 1.68 | K18: =I18*Assumptions!C15/100 -> 0.56 | L18: =I18+J18+K18 -> 7.84 | M18: Everest 2023 | N18: Technical Developer
B19: ERP – GL | C19: Journal Import Custom Validation Rule | D19: Business Rule | E19: H | F19: 2 | G19: 5 | H19: =IF(E19="L",Assumptions!E34,IF(E19="M",Assumptions!E35,IF(E19="H",Assumptions!E36,IF(E19="VH",Assumptions!E37,1)))) -> 1.5 | I19: =F19*G19*H19 -> 15 | J19: =I19*Assumptions!C13/100 -> 4.5 | K19: =I19*Assumptions!C15/100 -> 1.5 | L19: =I19+J19+K19 -> 21 | M19: Forrester TEI | N19: Technical Developer
B20: ERP – AP | C20: Custom Invoice Approval Workflow Ext | D20: Workflow Ext | E20: H | F20: 1 | G20: 8 | H20: =IF(E20="L",Assumptions!E34,IF(E20="M",Assumptions!E35,IF(E20="H",Assumptions!E36,IF(E20="VH",Assumptions!E37,1)))) -> 1.5 | I20: =F20*G20*H20 -> 12 | J20: =I20*Assumptions!C13/100 -> 3.6 | K20: =I20*Assumptions!C15/100 -> 1.2 | L20: =I20+J20+K20 -> 16.8 | M20: Gartner 2022 | N20: Technical Lead
C21: Custom Payment File Format (ISO20022) | D21: BI Publisher | E21: H | F21: 2 | G21: 8 | H21: =IF(E21="L",Assumptions!E34,IF(E21="M",Assumptions!E35,IF(E21="H",Assumptions!E36,IF(E21="VH",Assumptions!E37,1)))) -> 1.5 | I21: =F21*G21*H21 -> 24 | J21: =I21*Assumptions!C13/100 -> 7.2 | K21: =I21*Assumptions!C15/100 -> 2.4 | L21: =I21+J21+K21 -> 33.6 | M21: Forrester TEI | N21: Technical Lead
B22: ERP – AR | C22: Custom AutoInvoice Interface Validation | D22: Business Rule | E22: M | F22: 1 | G22: 5 | H22: =IF(E22="L",Assumptions!E34,IF(E22="M",Assumptions!E35,IF(E22="H",Assumptions!E36,IF(E22="VH",Assumptions!E37,1)))) -> 1 | I22: =F22*G22*H22 -> 5 | J22: =I22*Assumptions!C13/100 -> 1.5 | K22: =I22*Assumptions!C15/100 -> 0.5 | L22: =I22+J22+K22 -> 7 | M22: Everest 2023 | N22: Technical Developer
B23: ERP – FA | C23: Custom Asset Depreciation Report | D23: OTBI/BIP | E23: M | F23: 1 | G23: 6 | H23: =IF(E23="L",Assumptions!E34,IF(E23="M",Assumptions!E35,IF(E23="H",Assumptions!E36,IF(E23="VH",Assumptions!E37,1)))) -> 1 | I23: =F23*G23*H23 -> 6 | J23: =I23*Assumptions!C13/100 -> 1.8 | K23: =I23*Assumptions!C15/100 -> 0.6 | L23: =I23+J23+K23 -> 8.4 | M23: Everest 2023 | N23: Technical Developer
B24: ERP – Tax | C24: Tax Determination Custom Rule | D24: Business Rule | E24: H | F24: 3 | G24: 6 | H24: =IF(E24="L",Assumptions!E34,IF(E24="M",Assumptions!E35,IF(E24="H",Assumptions!E36,IF(E24="VH",Assumptions!E37,1)))) -> 1.5 | I24: =F24*G24*H24 -> 27 | J24: =I24*Assumptions!C13/100 -> 8.1 | K24: =I24*Assumptions!C15/100 -> 2.7 | L24: =I24+J24+K24 -> 37.8 | M24: Forrester TEI | N24: Technical Lead
B25: ERP – Proc | C25: Custom PO Approval Notification | D25: BPM Workflow | E25: M | F25: 1 | G25: 6 | H25: =IF(E25="L",Assumptions!E34,IF(E25="M",Assumptions!E35,IF(E25="H",Assumptions!E36,IF(E25="VH",Assumptions!E37,1)))) -> 1 | I25: =F25*G25*H25 -> 6 | J25: =I25*Assumptions!C13/100 -> 1.8 | K25: =I25*Assumptions!C15/100 -> 0.6 | L25: =I25+J25+K25 -> 8.4 | M25: Everest 2023 | N25: Technical Developer
C26: Supplier Portal Custom Page Extension | D26: Page Ext (VB) | E26: M | F26: 1 | G26: 5 | H26: =IF(E26="L",Assumptions!E34,IF(E26="M",Assumptions!E35,IF(E26="H",Assumptions!E36,IF(E26="VH",Assumptions!E37,1)))) -> 1 | I26: =F26*G26*H26 -> 5 | J26: =I26*Assumptions!C13/100 -> 1.5 | K26: =I26*Assumptions!C15/100 -> 0.5 | L26: =I26+J26+K26 -> 7 | M26: Everest 2023 | N26: Technical Developer
B27: SCM – OMS | C27: Custom Pricing Algorithm Extension | D27: Business Rule | E27: H | F27: 1 | G27: 10 | H27: =IF(E27="L",Assumptions!E34,IF(E27="M",Assumptions!E35,IF(E27="H",Assumptions!E36,IF(E27="VH",Assumptions!E37,1)))) -> 1.5 | I27: =F27*G27*H27 -> 15 | J27: =I27*Assumptions!C13/100 -> 4.5 | K27: =I27*Assumptions!C15/100 -> 1.5 | L27: =I27+J27+K27 -> 21 | M27: Gartner 2022 | N27: Technical Lead
C28: Custom Order Fulfilment Orchestration | D28: OIC Flow | E28: H | F28: 2 | G28: 10 | H28: =IF(E28="L",Assumptions!E34,IF(E28="M",Assumptions!E35,IF(E28="H",Assumptions!E36,IF(E28="VH",Assumptions!E37,1)))) -> 1.5 | I28: =F28*G28*H28 -> 30 | J28: =I28*Assumptions!C13/100 -> 9 | K28: =I28*Assumptions!C15/100 -> 3 | L28: =I28+J28+K28 -> 42 | M28: Forrester TEI | N28: Technical Lead
B29: SCM – MFG | C29: Custom Production Dispatch Report | D29: OTBI/BIP | E29: M | F29: 2 | G29: 5 | H29: =IF(E29="L",Assumptions!E34,IF(E29="M",Assumptions!E35,IF(E29="H",Assumptions!E36,IF(E29="VH",Assumptions!E37,1)))) -> 1 | I29: =F29*G29*H29 -> 10 | J29: =I29*Assumptions!C13/100 -> 3 | K29: =I29*Assumptions!C15/100 -> 1 | L29: =I29+J29+K29 -> 14 | M29: Everest 2023 | N29: Technical Developer
B30: SCM – WMS | C30: Custom Barcode Label Layout | D30: BI Publisher | E30: L | F30: 2 | G30: 3 | H30: =IF(E30="L",Assumptions!E34,IF(E30="M",Assumptions!E35,IF(E30="H",Assumptions!E36,IF(E30="VH",Assumptions!E37,1)))) -> 0.7 | I30: =F30*G30*H30 -> 4.2 | J30: =I30*Assumptions!C13/100 -> 1.26 | K30: =I30*Assumptions!C15/100 -> 0.42 | L30: =I30+J30+K30 -> 5.88 | M30: Everest 2023 | N30: Technical Developer
B31: Integration | C31: OIC Flow — HCM to Payroll Provider | D31: OIC (Complex) | E31: H | F31: 1 | G31: 14 | H31: =IF(E31="L",Assumptions!E34,IF(E31="M",Assumptions!E35,IF(E31="H",Assumptions!E36,IF(E31="VH",Assumptions!E37,1)))) -> 1.5 | I31: =F31*G31*H31 -> 21 | J31: =I31*Assumptions!C13/100 -> 6.3 | K31: =I31*Assumptions!C15/100 -> 2.1 | L31: =I31+J31+K31 -> 29.4 | M31: Everest 2023 | N31: Technical Lead
C32: OIC Flow — ERP to Banking (ISO20022) | D32: OIC (Complex) | E32: H | F32: 1 | G32: 14 | H32: =IF(E32="L",Assumptions!E34,IF(E32="M",Assumptions!E35,IF(E32="H",Assumptions!E36,IF(E32="VH",Assumptions!E37,1)))) -> 1.5 | I32: =F32*G32*H32 -> 21 | J32: =I32*Assumptions!C13/100 -> 6.3 | K32: =I32*Assumptions!C15/100 -> 2.1 | L32: =I32+J32+K32 -> 29.4 | M32: Forrester TEI | N32: Technical Lead
C33: OIC Flow — SCM to 3PL Warehouse | D33: OIC (Complex) | E33: H | F33: 2 | G33: 14 | H33: =IF(E33="L",Assumptions!E34,IF(E33="M",Assumptions!E35,IF(E33="H",Assumptions!E36,IF(E33="VH",Assumptions!E37,1)))) -> 1.5 | I33: =F33*G33*H33 -> 42 | J33: =I33*Assumptions!C13/100 -> 12.6 | K33: =I33*Assumptions!C15/100 -> 4.2 | L33: =I33+J33+K33 -> 58.8 | M33: Forrester TEI | N33: Technical Lead
C34: REST API — CRM to ERP Order | D34: OIC (Simple) | E34: M | F34: 3 | G34: 6 | H34: =IF(E34="L",Assumptions!E34,IF(E34="M",Assumptions!E35,IF(E34="H",Assumptions!E36,IF(E34="VH",Assumptions!E37,1)))) -> 1 | I34: =F34*G34*H34 -> 18 | J34: =I34*Assumptions!C13/100 -> 5.4 | K34: =I34*Assumptions!C15/100 -> 1.8 | L34: =I34+J34+K34 -> 25.2 | M34: Everest 2023 | N34: Technical Lead
C35: REST API — ERP to Tax Engine (Avalara) | D35: OIC (Simple) | E35: M | F35: 1 | G35: 8 | H35: =IF(E35="L",Assumptions!E34,IF(E35="M",Assumptions!E35,IF(E35="H",Assumptions!E36,IF(E35="VH",Assumptions!E37,1)))) -> 1 | I35: =F35*G35*H35 -> 8 | J35: =I35*Assumptions!C13/100 -> 2.4 | K35: =I35*Assumptions!C15/100 -> 0.8 | L35: =I35+J35+K35 -> 11.2 | M35: Everest 2023 | N35: Technical Lead
C36: File-Based SFTP Integration (batch) | D36: OIC (Simple) | E36: L | F36: 5 | G36: 4 | H36: =IF(E36="L",Assumptions!E34,IF(E36="M",Assumptions!E35,IF(E36="H",Assumptions!E36,IF(E36="VH",Assumptions!E37,1)))) -> 0.7 | I36: =F36*G36*H36 -> 14 | J36: =I36*Assumptions!C13/100 -> 4.2 | K36: =I36*Assumptions!C15/100 -> 1.4 | L36: =I36+J36+K36 -> 19.6 | M36: Everest 2023 | N36: Technical Developer
C37: Event-Driven ODA Chatbot Integration | D37: OIC (Complex) | E37: H | F37: 1 | G37: 16 | H37: =IF(E37="L",Assumptions!E34,IF(E37="M",Assumptions!E35,IF(E37="H",Assumptions!E36,IF(E37="VH",Assumptions!E37,1)))) -> 1.5 | I37: =F37*G37*H37 -> 24 | J37: =I37*Assumptions!C13/100 -> 7.2 | K37: =I37*Assumptions!C15/100 -> 2.4 | L37: =I37+J37+K37 -> 33.6 | M37: Gartner 2022 | N37: Technical Lead
B38: Reporting | C38: OTBI Analysis — GL Trial Balance | D38: OTBI | E38: M | F38: 2 | G38: 3 | H38: =IF(E34="L",Assumptions!E34,IF(E34="M",Assumptions!E35,IF(E34="H",Assumptions!E36,IF(E34="VH",Assumptions!E37,1)))) -> 1 | I38: =F38*G38*H38 -> 6 | J38: =I38*Assumptions!C13/100 -> 1.8 | K38: =I38*Assumptions!C15/100 -> 0.6 | L38: =I38+J38+K38 -> 8.4 | M38: Everest 2023 | N38: Technical Developer
I39: =F39*G39*H39 -> 0 | J39: =I39*Assumptions!C8/100 -> 0 | K39: =I39*Assumptions!C10/100 -> 0 | L39: =I39+J39+K39 -> 0 | M39: Everest 2023 | N39: Technical Developer
I40: =F40*G40*H40 -> 0 | J40: =I40*Assumptions!C8/100 -> 0 | K40: =I40*Assumptions!C10/100 -> 0 | L40: =I40+J40+K40 -> 0 | M40: Everest 2023 | N40: Technical Developer
C41: BIP Report — PO Output Format | D41: BI Publisher | E41: M | F41: 1 | G41: 5 | H41: =IF(E37="L",Assumptions!E34,IF(E37="M",Assumptions!E35,IF(E37="H",Assumptions!E36,IF(E37="VH",Assumptions!E37,1)))) -> 1.5 | I41: =F41*G41*H41 -> 7.5 | J41: =I41*Assumptions!C13/100 -> 2.25 | K41: =I41*Assumptions!C15/100 -> 0.75 | L41: =I41+J41+K41 -> 10.5 | M41: Everest 2023 | N41: Technical Developer
C42: OAC Dashboard — Finance KPIs | D42: OAC | E42: H | F42: 2 | G42: 10 | H42: =IF(E42="L",Assumptions!E34,IF(E42="M",Assumptions!E35,IF(E42="H",Assumptions!E36,IF(E42="VH",Assumptions!E37,1)))) -> 1.5 | I42: =F42*G42*H42 -> 30 | J42: =I42*Assumptions!C13/100 -> 9 | K42: =I42*Assumptions!C15/100 -> 3 | L42: =I42+J42+K42 -> 42 | M42: Gartner 2022 | N42: Technical Lead
C43: OAC Dashboard — Supply Chain Ops | D43: OAC | E43: H | F43: 1 | G43: 10 | H43: =IF(E43="L",Assumptions!E34,IF(E43="M",Assumptions!E35,IF(E43="H",Assumptions!E36,IF(E43="VH",Assumptions!E37,1)))) -> 1.5 | I43: =F43*G43*H43 -> 15 | J43: =I43*Assumptions!C13/100 -> 4.5 | K43: =I43*Assumptions!C15/100 -> 1.5 | L43: =I43+J43+K43 -> 21 | M43: Gartner 2022 | N43: Technical Lead
...

Sheet Data Migration Est.
B1: DATA MIGRATION EFFORT ESTIMATOR
B2: Bottom-up per migration object: Extract + Cleanse + Transform + Load + Recon/UT | Amber = input
B4: UT / Reconciliation Days = (Extract+Cleanse+Transform+Load) × UT% from Assumptions C9 | All effort is per migration object (one FBDI/HDL template). Volume = number of trial load cycles (default 3).
B6: Module | C6: Migration Object | D6: Tool (FBDI/HDL) | E6: CX (L/M/H) | F6: Trial Loads (Vol) | G6: Extract Days | H6: Cleanse Days | I6: Transform Days | J6: Load Days | K6: Recon/UT Days | L6: Sub-Total Dev Days | M6: Total incl UT (Days) | N6: Benchmark / Role
B7: ▼ COMPLEXITY GUIDE — Data Migration objects (Column E)
B8: Select the code that best describes the majority of the work in this row. When in doubt between two levels, always choose the higher one and document your rationale. Multipliers are applied automatically from the Assumptions tab.
B9: Level (Code) | E9: Selection Criteria | N9: Typical Example for this Sheet
B10: Low (L) ×0.7× | E10: • OOB / standard Oracle functionality; minimal configuration beyond defaults • Single legal entity or business unit; no country-specific localisation • Processes closely match Oracle standard; no workarounds or process redesign • Standard approval workflow (1–2 levels); standard RBAC roles sufficient • Source data is clean, well-structured, available in compatible format • Integration is one-way batch/file-based (SFTP/FTP); no transformation logic | N10: › Reference data (departments, grades, jobs) — clean single source › Supplier master from single ERP, no duplicates, standard fields › GL chart of accounts with clear legacy mapping
B11: Medium (M) ×1.0× | E11: • Some configuration beyond OOB; guided by Oracle best practice • 2–5 legal entities or business units sharing common structures • Minor process deviations handled via Oracle flexfields or lookups • Standard multi-level approval workflow (2–3 levels); standard security model • Source data requires moderate cleansing; mostly 1-to-1 field mapping • Standard REST/SOAP API integration; moderate transformation logic | N11: › Employee master from a single HR system with standard fields › Open AP invoices from a structured ERP with known schema › Item master with 50–70% direct attribute mapping
B12: High (H) ×1.4× | E12: • Significant complexity; multiple exceptions to OOB process • 6–15 legal entities, multi-country, or cross-pillar dependencies • Legislative or regulatory requirements driving non-standard configuration • Complex multi-level approval hierarchies; data security policy design • Source data is poor quality, fragmented across systems, or unstructured • Real-time or bidirectional integration; event-driven or orchestrated flows | N12: › Employee data from 3+ HR systems with conflicting schemas › Fixed assets with full depreciation history and NBV reconciliation › BOM/routing from legacy MRP with non-standard structure and UoM
B13: Very High (VH) ×2.0× | E13: • Heavily customised or non-standard process; Oracle OOB not fit for purpose • 15+ legal entities, global rollout, or highly regulated (BFSI, Pharma, Defence) • High CEMLI dependency; multiple custom extensions interacting with each other • Real-time multi-system orchestration with complex event handling and retry logic • Legacy data with no clear mapping, large volumes, or critical statutory reconciliation • Concurrent go-live across multiple countries or business units in a single cutover | N13: › Legacy COBOL mainframe data with reverse-engineered schema › Multi-country payroll balances with local statutory year-end carryforward › Inventory from 5+ legacy WMS systems with conflicting UoM, codes and structures
B15: HCM | C15: Employees (Person, Assignment, Contract) | D15: HDL | E15: H | F15: 1 | G15: 8 | H15: 12 | I15: 6 | J15: 4 | K15: 4 | L15: =(G15+H15+I15+J15)*F15*(IF(E15="L",Assumptions!D34,IF(E15="M",Assumptions!D35,IF(E15="H",Assumptions!D36,1)))) -> 42 | M15: =L15+K15*F15*(IF(E15="L",Assumptions!D34,IF(E15="M",Assumptions!D35,IF(E15="H",Assumptions!D36,1))))+L15*Assumptions!C14/100 -> 58.1 | N15: Everest 2023 | DM Specialist
C16: Organisation Hierarchy & Departments | D16: HDL | E16: M | F16: 1 | G16: 3 | H16: 5 | I16: 3 | J16: 2 | K16: 2 | L16: =(G16+H16+I16+J16)*F16*(IF(E16="L",Assumptions!D34,IF(E16="M",Assumptions!D35,IF(E16="H",Assumptions!D36,1)))) -> 13 | M16: =L16+K16*F16*(IF(E16="L",Assumptions!D34,IF(E16="M",Assumptions!D35,IF(E16="H",Assumptions!D36,1))))+L16*Assumptions!C14/100 -> 18.25 | N16: Everest 2023 | DM Specialist
C17: Jobs, Positions & Grades | D17: HDL | E17: M | F17: 1 | G17: 2 | H17: 3 | I17: 2 | J17: 2 | K17: 1 | L17: =(G17+H17+I17+J17)*F17*(IF(E17="L",Assumptions!D34,IF(E17="M",Assumptions!D35,IF(E17="H",Assumptions!D36,1)))) -> 9 | M17: =L17+K17*F17*(IF(E17="L",Assumptions!D34,IF(E17="M",Assumptions!D35,IF(E17="H",Assumptions!D36,1))))+L17*Assumptions!C14/100 -> 12.25 | N17: Everest 2023 | Functional Consultant
C18: Work Relationships & Contracts | D18: HDL | E18: H | F18: 1 | G18: 4 | H18: 6 | I18: 4 | J18: 3 | K18: 3 | L18: =(G18+H18+I18+J18)*F18*(IF(E18="L",Assumptions!D34,IF(E18="M",Assumptions!D35,IF(E18="H",Assumptions!D36,1)))) -> 23.8 | M18: =L18+K18*F18*(IF(E18="L",Assumptions!D34,IF(E18="M",Assumptions!D35,IF(E18="H",Assumptions!D36,1))))+L18*Assumptions!C14/100 -> 33.95 | N18: Everest 2023 | DM Specialist
C19: Compensation & Salary History | D19: HCM Spreadsheet | E19: H | F19: 1 | G19: 4 | H19: 8 | I19: 4 | J19: 3 | K19: 3 | L19: =(G19+H19+I19+J19)*F19*(IF(E19="L",Assumptions!D34,IF(E19="M",Assumptions!D35,IF(E19="H",Assumptions!D36,1)))) -> 26.6 | M19: =L19+K19*F19*(IF(E19="L",Assumptions!D34,IF(E19="M",Assumptions!D35,IF(E19="H",Assumptions!D36,1))))+L19*Assumptions!C14/100 -> 37.45 | N19: Forrester TEI | DM Specialist
C20: Absence Balances & Accruals | D20: HCM Spreadsheet | E20: M | F20: 1 | G20: 2 | H20: 4 | I20: 3 | J20: 2 | K20: 2 | L20: =(G20+H20+I20+J20)*F20*(IF(E20="L",Assumptions!D34,IF(E20="M",Assumptions!D35,IF(E20="H",Assumptions!D36,1)))) -> 11 | M20: =L20+K20*F20*(IF(E20="L",Assumptions!D34,IF(E20="M",Assumptions!D35,IF(E20="H",Assumptions!D36,1))))+L20*Assumptions!C14/100 -> 15.75 | N20: Everest 2023 | DM Specialist
B21: ERP | C21: Chart of Accounts & Account Values | D21: FBDI | E21: H | F21: 1 | G21: 3 | H21: 5 | I21: 3 | J21: 2 | K21: 3 | L21: =(G21+H21+I21+J21)*F21*(IF(E21="L",Assumptions!D34,IF(E21="M",Assumptions!D35,IF(E21="H",Assumptions!D36,1)))) -> 18.2 | M21: =L21+K21*F21*(IF(E21="L",Assumptions!D34,IF(E21="M",Assumptions!D35,IF(E21="H",Assumptions!D36,1))))+L21*Assumptions!C14/100 -> 26.95 | N21: Everest 2023 | DM Specialist
C22: Open AP Invoices | D22: FBDI | E22: H | F22: 1 | G22: 3 | H22: 6 | I22: 4 | J22: 3 | K22: 4 | L22: =(G22+H22+I22+J22)*F22*(IF(E22="L",Assumptions!D34,IF(E22="M",Assumptions!D35,IF(E22="H",Assumptions!D36,1)))) -> 22.4 | M22: =L22+K22*F22*(IF(E22="L",Assumptions!D34,IF(E22="M",Assumptions!D35,IF(E22="H",Assumptions!D36,1))))+L22*Assumptions!C14/100 -> 33.6 | N22: Forrester TEI | DM Specialist
C23: Open AR Transactions | D23: FBDI | E23: H | F23: 1 | G23: 3 | H23: 6 | I23: 4 | J23: 3 | K23: 4 | L23: =(G23+H23+I23+J23)*F23*(IF(E23="L",Assumptions!D34,IF(E23="M",Assumptions!D35,IF(E23="H",Assumptions!D36,1)))) -> 22.4 | M23: =L23+K23*F23*(IF(E23="L",Assumptions!D34,IF(E23="M",Assumptions!D35,IF(E23="H",Assumptions!D36,1))))+L23*Assumptions!C14/100 -> 33.6 | N23: Forrester TEI | DM Specialist
C24: Fixed Assets — Asset Details & NBV | D24: FBDI | E24: H | F24: 1 | G24: 4 | H24: 8 | I24: 5 | J24: 4 | K24: 5 | L24: =(G24+H24+I24+J24)*F24*(IF(E24="L",Assumptions!D34,IF(E24="M",Assumptions!D35,IF(E24="H",Assumptions!D36,1)))) -> 29.4 | M24: =L24+K24*F24*(IF(E24="L",Assumptions!D34,IF(E24="M",Assumptions!D35,IF(E24="H",Assumptions!D36,1))))+L24*Assumptions!C14/100 -> 43.75 | N24: Gartner 2022 | DM Specialist
C25: GL Open Balances (per period) | D25: FBDI | E25: M | F25: 1 | G25: 3 | H25: 4 | I25: 3 | J25: 2 | K25: 3 | L25: =(G25+H25+I25+J25)*F25*(IF(E25="L",Assumptions!D34,IF(E25="M",Assumptions!D35,IF(E25="H",Assumptions!D36,1)))) -> 12 | M25: =L25+K25*F25*(IF(E25="L",Assumptions!D34,IF(E25="M",Assumptions!D35,IF(E25="H",Assumptions!D36,1))))+L25*Assumptions!C14/100 -> 18 | N25: Everest 2023 | DM Specialist
C26: Supplier Master & Supplier Sites | D26: FBDI | E26: M | F26: 1 | G26: 3 | H26: 5 | I26: 3 | J26: 2 | K26: 2 | L26: =(G26+H26+I26+J26)*F26*(IF(E26="L",Assumptions!D34,IF(E26="M",Assumptions!D35,IF(E26="H",Assumptions!D36,1)))) -> 13 | M26: =L26+K26*F26*(IF(E26="L",Assumptions!D34,IF(E26="M",Assumptions!D35,IF(E26="H",Assumptions!D36,1))))+L26*Assumptions!C14/100 -> 18.25 | N26: Everest 2023 | Functional Consultant
C27: Customer Master & Customer Sites | D27: FBDI | E27: M | F27: 1 | G27: 3 | H27: 5 | I27: 3 | J27: 2 | K27: 2 | L27: =(G27+H27+I27+J27)*F27*(IF(E27="L",Assumptions!D34,IF(E27="M",Assumptions!D35,IF(E27="H",Assumptions!D36,1)))) -> 13 | M27: =L27+K27*F27*(IF(E27="L",Assumptions!D34,IF(E27="M",Assumptions!D35,IF(E27="H",Assumptions!D36,1))))+L27*Assumptions!C14/100 -> 18.25 | N27: Everest 2023 | Functional Consultant
L28: =(G28+H28+I28+J28)*F28*(IF(E28="L",Assumptions!D38,IF(E28="M",Assumptions!D39,IF(E28="H",Assumptions!D40,1)))) -> 0 | M28: =L28+K28*F28*(IF(E28="L",Assumptions!D38,IF(E28="M",Assumptions!D39,IF(E28="H",Assumptions!D40,1))))+L28*Assumptions!C9/100 -> 0 | N28: Everest 2023 | DM Specialist
B29: SCM | L29: =(G29+H29+I29+J29)*F29*(IF(E29="L",Assumptions!D38,IF(E29="M",Assumptions!D39,IF(E29="H",Assumptions!D40,1)))) -> 0 | M29: =L29+K29*F29*(IF(E29="L",Assumptions!D38,IF(E29="M",Assumptions!D39,IF(E29="H",Assumptions!D40,1))))+L29*Assumptions!C9/100 -> 0 | N29: Everest 2023 | DM Specialist
C30: Bill of Materials (BOM) | D30: FBDI | E30: H | F30: 1 | G30: 4 | H30: 8 | I30: 5 | J30: 4 | K30: 4 | L30: =(G30+H30+I30+J30)*F30*(IF(E30="L",Assumptions!D34,IF(E30="M",Assumptions!D35,IF(E30="H",Assumptions!D36,1)))) -> 29.4 | M30: =L30+K30*F30*(IF(E30="L",Assumptions!D34,IF(E30="M",Assumptions!D35,IF(E30="H",Assumptions!D36,1))))+L30*Assumptions!C14/100 -> 42.35 | N30: Gartner 2022 | DM Specialist
C31: On-Hand Inventory Balances | D31: FBDI | E31: M | F31: 1 | G31: 3 | H31: 5 | I31: 3 | J31: 3 | K31: 3 | L31: =(G31+H31+I31+J31)*F31*(IF(E31="L",Assumptions!D34,IF(E31="M",Assumptions!D35,IF(E31="H",Assumptions!D36,1)))) -> 14 | M31: =L31+K31*F31*(IF(E31="L",Assumptions!D34,IF(E31="M",Assumptions!D35,IF(E31="H",Assumptions!D36,1))))+L31*Assumptions!C14/100 -> 20.5 | N31: Everest 2023 | DM Specialist
C32: Open Sales Orders | D32: FBDI | E32: H | F32: 1 | G32: 4 | H32: 6 | I32: 4 | J32: 3 | K32: 3 | L32: =(G32+H32+I32+J32)*F32*(IF(E32="L",Assumptions!D34,IF(E32="M",Assumptions!D35,IF(E32="H",Assumptions!D36,1)))) -> 23.8 | M32: =L32+K32*F32*(IF(E32="L",Assumptions!D34,IF(E32="M",Assumptions!D35,IF(E32="H",Assumptions!D36,1))))+L32*Assumptions!C14/100 -> 33.95 | N32: Everest 2023 | DM Specialist
C33: Routings & Resources | D33: FBDI | E33: H | F33: 1 | G33: 3 | H33: 6 | I33: 4 | J33: 3 | K33: 3 | L33: =(G33+H33+I33+J33)*F33*(IF(E33="L",Assumptions!D34,IF(E33="M",Assumptions!D35,IF(E33="H",Assumptions!D36,1)))) -> 22.4 | M33: =L33+K33*F33*(IF(E33="L",Assumptions!D34,IF(E33="M",Assumptions!D35,IF(E33="H",Assumptions!D36,1))))+L33*Assumptions!C14/100 -> 32.2 | N33: Everest 2023 | DM Specialist
B34: EPM | C34: Historical Financial Data (FCCS) | D34: Data Management | E34: H | F34: 1 | G34: 5 | H34: 10 | I34: 6 | J34: 4 | K34: 5 | L34: =(G34+H34+I34+J34)*F34*(IF(E34="L",Assumptions!D34,IF(E34="M",Assumptions!D35,IF(E34="H",Assumptions!D36,1)))) -> 35 | M34: =L34+K34*F34*(IF(E34="L",Assumptions!D34,IF(E34="M",Assumptions!D35,IF(E34="H",Assumptions!D36,1))))+L34*Assumptions!C14/100 -> 50.75 | N34: Gartner 2022 | DM Specialist
C35: Budget / Plan Data (EPBCS) | D35: Data Management | E35: M | F35: 1 | G35: 3 | H35: 5 | I35: 4 | J35: 3 | K35: 3 | L35: =(G35+H35+I35+J35)*F35*(IF(E35="L",Assumptions!D34,IF(E35="M",Assumptions!D35,IF(E35="H",Assumptions!D36,1)))) -> 15 | M35: =L35+K35*F35*(IF(E35="L",Assumptions!D34,IF(E35="M",Assumptions!D35,IF(E35="H",Assumptions!D36,1))))+L35*Assumptions!C14/100 -> 21.75 | N35: Gartner 2022 | DM Specialist
B36: DATA MIGRATION TOTALS | L36: =SUM(L15:L35) -> 395.4 | M36: =SUM(M15:M35) -> 569.65
B37: TOTAL DATA MIGRATION WITH CONTINGENCY | M37: =M36*(1+Assumptions!C8/100) -> 655.0975

Sheet SDLC Phase View
B1: SDLC PHASE EFFORT VIEW
B2: Cross-stream effort rolled up by SDLC phase | References Config, Custom & Data Migration sheets
B4: A. SOURCE STREAM TOTALS (with Contingency)
B5: Stream | C5: Total Effort (Days) | D5: Dev Days | E5: UT / Recon Days | F5: Source Sheet
B6: Configuration | C6: ='Config Estimator'!K72 -> 643.356 | D6: ='Config Estimator'!I72 -> 0 | E6: ='Config Estimator'!J72 -> 0 | F6: Config Estimator — Col K
B7: Customisation (CEMLI) | C7: ='Custom Estimator'!L48 -> 748.328 | D7: ='Custom Estimator'!I48 -> 0 | E7: ='Custom Estimator'!J48+('Custom Estimator'!K48) -> 0 | F7: Custom Estimator — Col L
B8: Data Migration | C8: ='Data Migration Est.'!M37 -> 655.0975 | D8: ='Data Migration Est.'!L37 -> 0 | E8: ='Data Migration Est.'!K37 -> 0 | F8: Data Migration Est. — Col M
B9: GRAND TOTAL (all streams) | C9: =C6+C7+C8 -> 2046.7815 | D9: =D6+D7+D8 -> 0 | E9: =E6+E7+E8 -> 0
B11: B. EFFORT BY SDLC PHASE — ALL STREAMS
B12: SDLC Phase | C12: Config Effort | D12: Custom Effort | E12: Data Mig Effort | F12: Total Phase Effort | G12: % of Grand Total | H12: Elapsed Weeks (est) | I12: Phase FTE (avg)
B13: Ph0: Inception/Mobilise | C13: =0.03*C6 -> 19.30068 | D13: =0.02*C7 -> 14.96656 | E13: =0.05*C8 -> 32.754875 | F13: =C13+D13+E13 -> 67.022115 | G13: =IFERROR(F13/C9,0) -> 0.032745124 | H13: =(5/100)*18*4.3 -> 3.87 | I13: =IFERROR(F13/(H13*Assumptions!C2),0) -> 0
B14: Ph1: Discover & Assess | C14: =0.12*C6 -> 77.20272 | D14: =0.05*C7 -> 37.4164 | E14: =0.15*C8 -> 98.264625 | F14: =C14+D14+E14 -> 212.88375 | G14: =IFERROR(F14/C9,0) -> 0.10400902 | H14: =(12/100)*18*4.3 -> 9.288 | I14: =IFERROR(F14/(H14*Assumptions!C2),0) -> 0
B15: Ph2: Design/Blueprint | C15: =0.18*C6 -> 115.80408 | D15: =0.15*C7 -> 112.2492 | E15: =0.1*C8 -> 65.50975 | F15: =C15+D15+E15 -> 293.56303 | G15: =IFERROR(F15/C9,0) -> 0.14342666 | H15: =(18/100)*18*4.3 -> 13.932 | I15: =IFERROR(F15/(H15*Assumptions!C2),0) -> 0
B16: Ph3: Build / Configure | C16: =0.4*C6 -> 257.3424 | D16: =0.45*C7 -> 336.7476 | E16: =0.25*C8 -> 163.77437 | F16: =C16+D16+E16 -> 757.86437 | G16: =IFERROR(F16/C9,0) -> 0.37027126 | H16: =(28/100)*18*4.3 -> 21.672 | I16: =IFERROR(F16/(H16*Assumptions!C2),0) -> 0
B17: Ph4: Integration & SIT | C17: =0.1*C6 -> 64.3356 | D17: =0.18*C7 -> 134.69904 | E17: =0.05*C8 -> 32.754875 | F17: =C17+D17+E17 -> 231.78951 | G17: =IFERROR(F17/C9,0) -> 0.11324585 | H17: =(12/100)*18*4.3 -> 9.288 | I17: =IFERROR(F17/(H17*Assumptions!C2),0) -> 0
B18: Ph5: UAT | C18: =0.08*C6 -> 51.46848 | D18: =0.1*C7 -> 74.8328 | E18: =0.05*C8 -> 32.754875 | F18: =C18+D18+E18 -> 159.05615 | G18: =IFERROR(F18/C9,0) -> 0.077710374 | H18: =(8/100)*18*4.3 -> 6.192 | I18: =IFERROR(F18/(H18*Assumptions!C2),0) -> 0
B19: Ph6: Data Migration | C19: =0*C6 -> 0 | D19: =0*C7 -> 0 | E19: =0.25*C8 -> 163.77437 | F19: =C19+D19+E19 -> 163.77437 | G19: =IFERROR(F19/C9,0) -> 0.080015563 | H19: =(8/100)*18*4.3 -> 6.192 | I19: =IFERROR(F19/(H19*Assumptions!C2),0) -> 0
B20: Ph7: Training & OCM | C20: =0.04*C6 -> 25.73424 | D20: =0.02*C7 -> 14.96656 | E20: =0.03*C8 -> 19.652925 | F20: =C20+D20+E20 -> 60.353725 | G20: =IFERROR(F20/C9,0) -> 0.029487136 | H20: =(5/100)*18*4.3 -> 3.87 | I20: =IFERROR(F20/(H20*Assumptions!C2),0) -> 0
B21: Ph8: Go-Live & Cutover | C21: =0.03*C6 -> 19.30068 | D21: =0.02*C7 -> 14.96656 | E21: =0.05*C8 -> 32.754875 | F21: =C21+D21+E21 -> 67.022115 | G21: =IFERROR(F21/C9,0) -> 0.032745124 | H21: =(2/100)*18*4.3 -> 1.548 | I21: =IFERROR(F21/(H21*Assumptions!C2),0) -> 0
B22: Ph9: Post Go-Live/Hypercare | C22: =0.02*C6 -> 12.86712 | D22: =0.01*C7 -> 7.48328 | E22: =0.02*C8 -> 13.10195 | F22: =C22+D22+E22 -> 33.45235 | G22: =IFERROR(F22/C9,0) -> 0.016343879 | H22: =(2/100)*18*4.3 -> 1.548 | I22: =IFERROR(F22/(H22*Assumptions!C2),0) -> 0
B23: TOTAL | C23: =SUM(C13:C22) -> 643.356 | D23: =SUM(D13:D22) -> 748.328 | E23: =SUM(E13:E22) -> 655.0975 | F23: =SUM(F13:F22) -> 2046.7815
B25: C. PHASE DEFINITIONS & KEY DELIVERABLES
B26: Phase | C26: Oracle OUM Ref | D26: % Config | E26: % Custom | F26: % DataMig | G26: Key Activities / Deliverables
B27: Ph0: Inception/Mobilise | C27: Phase 0 | D27: 3% | E27: 2% | F27: 5% | G27: Infra, kick-off, governance, templates
B28: Ph1: Discover & Assess | C28: OUM: Inception | D28: 12% | E28: 5% | F28: 15% | G28: CRP1, current state, gap analysis
B29: Ph2: Design/Blueprint | C29: OUM: Elaboration | D29: 18% | E29: 15% | F29: 10% | G29: Future state, CRP2, solution design
B30: Ph3: Build / Configure | C30: OUM: Construction | D30: 40% | E30: 45% | F30: 25% | G30: Config, Dev, Unit Test — heaviest phase
B31: Ph4: Integration & SIT | C31: OUM: Construction | D31: 10% | E31: 18% | F31: 5% | G31: OIC flows, SIT, defect cycles
B32: Ph5: UAT | C32: OUM: Transition | D32: 8% | E32: 10% | F32: 5% | G32: Business-led UAT, defect fix, sign-off
B33: Ph6: Data Migration | C33: OUM: Transition | D33: 0% | E33: 0% | F33: 25% | G33: Trial loads, reconciliation, cutover data
B34: Ph7: Training & OCM | C34: OUM: Transition | D34: 4% | E34: 2% | F34: 3% | G34: Training delivery, change comms
B35: Ph8: Go-Live & Cutover | C35: OUM: Production | D35: 3% | E35: 2% | F35: 5% | G35: Cutover weekend, parallel run
B36: Ph9: Post Go-Live/Hypercare | C36: OUM: Production | D36: 2% | E36: 1% | F36: 2% | G36: Stabilisation, L1/L2 hypercare

Sheet Role & FTE Summary
B1: ROLE EFFORT & FTE SUMMARY
B2: Effort by role across all three streams | FTE = Effort ÷ (Project Months × Working Days/Month)
B4: A. EFFORT BY ROLE — CROSS-STREAM SUMMARY
B5: Role / Band | C5: Config Days | D5: Custom Days | E5: Data Mig Days | F5: Total Days | G5: % of Total | H5: Avg FTE (18 mths) | I5: Peak FTE
B6: Programme Director | C6: =0.02*'Config Estimator'!K72 -> 12.86712 | D6: =0.01*'Custom Estimator'!L48 -> 7.48328 | E6: =0.01*'Data Migration Est.'!M37 -> 6.550975 | F6: =C6+D6+E6 -> 26.901375 | G6: =IFERROR(F6/F21,0) -> 0.013018257 | H6: =IFERROR(F6/(18*Assumptions!C2),0) -> 0 | I6: =IFERROR(CEILING(H6*2,0.5),0) -> 0
B7: Solution Architect | C7: =0.05*'Config Estimator'!K72 -> 32.1678 | D7: =0.06*'Custom Estimator'!L48 -> 44.89968 | E7: =0.03*'Data Migration Est.'!M37 -> 19.652925 | F7: =C7+D7+E7 -> 96.720405 | G7: =IFERROR(F7/F21,0) -> 0.046805456 | H7: =IFERROR(F7/(18*Assumptions!C2),0) -> 0 | I7: =IFERROR(CEILING(H7*2,0.5),0) -> 0
B8: Functional Lead (HCM) | C8: =0.12*'Config Estimator'!K72 -> 77.20272 | D8: =0.01*'Custom Estimator'!L48 -> 7.48328 | E8: =0.04*'Data Migration Est.'!M37 -> 26.2039 | F8: =C8+D8+E8 -> 110.8899 | G8: =IFERROR(F8/F21,0) -> 0.053662434 | H8: =IFERROR(F8/(18*Assumptions!C2),0) -> 0 | I8: =IFERROR(CEILING(H8*2,0.5),0) -> 0
B9: Functional Lead (Finance) | C9: =0.11*'Config Estimator'!K72 -> 70.76916 | D9: =0.01*'Custom Estimator'!L48 -> 7.48328 | E9: =0.06*'Data Migration Est.'!M37 -> 39.30585 | F9: =C9+D9+E9 -> 117.55829 | G9: =IFERROR(F9/F21,0) -> 0.056889436 | H9: =IFERROR(F9/(18*Assumptions!C2),0) -> 0 | I9: =IFERROR(CEILING(H9*2,0.5),0) -> 0
B10: Functional Lead (SCM) | C10: =0.1*'Config Estimator'!K72 -> 64.3356 | D10: =0.01*'Custom Estimator'!L48 -> 7.48328 | E10: =0.06*'Data Migration Est.'!M37 -> 39.30585 | F10: =C10+D10+E10 -> 111.12473 | G10: =IFERROR(F10/F21,0) -> 0.053776074 | H10: =IFERROR(F10/(18*Assumptions!C2),0) -> 0 | I10: =IFERROR(CEILING(H10*2,0.5),0) -> 0
B11: Technical/Integration Lead | C11: =0.03*'Config Estimator'!K72 -> 19.30068 | D11: =0.22*'Custom Estimator'!L48 -> 164.63216 | E11: =0.05*'Data Migration Est.'!M37 -> 32.754875 | F11: =C11+D11+E11 -> 216.68771 | G11: =IFERROR(F11/F21,0) -> 0.10486068 | H11: =IFERROR(F11/(18*Assumptions!C2),0) -> 0 | I11: =IFERROR(CEILING(H11*2,0.5),0) -> 0
B12: Functional Consultant Sr. | C12: =0.2*'Config Estimator'!K72 -> 128.6712 | D12: =0.02*'Custom Estimator'!L48 -> 14.96656 | E12: =0.08*'Data Migration Est.'!M37 -> 52.4078 | F12: =C12+D12+E12 -> 196.04556 | G12: =IFERROR(F12/F21,0) -> 0.094871416 | H12: =IFERROR(F12/(18*Assumptions!C2),0) -> 0 | I12: =IFERROR(CEILING(H12*2,0.5),0) -> 0
B13: Functional Consultant Mid | C13: =0.18*'Config Estimator'!K72 -> 115.80408 | D13: =0.02*'Custom Estimator'!L48 -> 14.96656 | E13: =0.06*'Data Migration Est.'!M37 -> 39.30585 | F13: =C13+D13+E13 -> 170.07649 | G13: =IFERROR(F13/F21,0) -> 0.082304325 | H13: =IFERROR(F13/(18*Assumptions!C2),0) -> 0 | I13: =IFERROR(CEILING(H13*2,0.5),0) -> 0
B14: ABAP/OIC Developer Sr. | C14: =0.02*'Config Estimator'!K72 -> 12.86712 | D14: =0.25*'Custom Estimator'!L48 -> 187.082 | E14: =0.04*'Data Migration Est.'!M37 -> 26.2039 | F14: =C14+D14+E14 -> 226.15302 | G14: =IFERROR(F14/F21,0) -> 0.10944118 | H14: =IFERROR(F14/(18*Assumptions!C2),0) -> 0 | I14: =IFERROR(CEILING(H14*2,0.5),0) -> 0
B15: ABAP/OIC Developer Mid | C15: =0.01*'Config Estimator'!K72 -> 6.43356 | D15: =0.2*'Custom Estimator'!L48 -> 149.6656 | E15: =0.03*'Data Migration Est.'!M37 -> 19.652925 | F15: =C15+D15+E15 -> 175.75208 | G15: =IFERROR(F15/F21,0) -> 0.085050889 | H15: =IFERROR(F15/(18*Assumptions!C2),0) -> 0 | I15: =IFERROR(CEILING(H15*2,0.5),0) -> 0
B16: Data Migration Specialist | C16: =0.02*'Config Estimator'!K72 -> 12.86712 | D16: =0.02*'Custom Estimator'!L48 -> 14.96656 | E16: =0.45*'Data Migration Est.'!M37 -> 294.79388 | F16: =C16+D16+E16 -> 322.62755 | G16: =IFERROR(F16/F21,0) -> 0.15612765 | H16: =IFERROR(F16/(18*Assumptions!C2),0) -> 0 | I16: =IFERROR(CEILING(H16*2,0.5),0) -> 0
B17: Change Mgmt / OCM Lead | C17: =0.03*'Config Estimator'!K72 -> 19.30068 | D17: =0.01*'Custom Estimator'!L48 -> 7.48328 | E17: =0.02*'Data Migration Est.'!M37 -> 13.10195 | F17: =C17+D17+E17 -> 39.88591 | G17: =IFERROR(F17/F21,0) -> 0.019301803 | H17: =IFERROR(F17/(18*Assumptions!C2),0) -> 0 | I17: =IFERROR(CEILING(H17*2,0.5),0) -> 0
B18: Testing Lead / QA | C18: =0.04*'Config Estimator'!K72 -> 25.73424 | D18: =0.08*'Custom Estimator'!L48 -> 59.86624 | E18: =0.05*'Data Migration Est.'!M37 -> 32.754875 | F18: =C18+D18+E18 -> 118.35536 | G18: =IFERROR(F18/F21,0) -> 0.057275156 | H18: =IFERROR(F18/(18*Assumptions!C2),0) -> 0 | I18: =IFERROR(CEILING(H18*2,0.5),0) -> 0
